Workbook
Name acs_19013_income_2024: income!$A$1:$OD$2
Name acs_b01001_sex_age_2024: sex_age!$A$1:$OD$50
Name acs_b02001_race_2024: race!$A$1:$OD$11
Name acs_b30001_hispanic_2024: hispanic!$A$1:$OD$32
Name combined_trends_wnba: combined_trends_wnba!$A$1:$N$53
Name conversion_gap_1: conversion_gap!$A$1:$E$12
Name interest_proxies_1: interest_proxies!$A$1:$G$573
Name missed_revenue_opportunity_1: missed_revenue_opportunity!$A$1:$E$12
Name wnba_attendance: game_attendance!$A$1:$F$14

Sheet game_attendance
A1: team | B1: num_games | C1: low | D1: high | E1: total | F1: avg
A2: Golden State Valkyries | B2: 23 | C2: 18064 | D2: 18543 | E2: 415951 | F2: 18084.826
A3: Indiana Fever | B3: 25 | C3: 15012 | D3: 17274 | E3: 413536 | F3: 16541.44
A4: New York Liberty | B4: 23 | C4: 14774 | D4: 17532 | E4: 376124 | F4: 16353.217
A5: Los Angeles Sparks | B5: 22 | C5: 10581 | D5: 18199 | E5: 273709 | F5: 12441.318
A6: Phoenix Mercury | B6: 28 | C6: 8024 | D6: 17071 | E6: 338932 | F6: 12104.714
A7: Seattle Storm | B7: 23 | C7: 9091 | D7: 18343 | E7: 272877 | F7: 11864.217
A8: Las Vegas Aces | B8: 29 | C8: 10266 | D8: 18547 | E8: 327103 | F8: 11279.414
A9: Minnesota Lynx | B9: 25 | C9: 7808 | D9: 16421 | E9: 248834 | F9: 9953.36
A10: Chicago Sky | B10: 22 | C10: 6572 | D10: 19601 | E10: 199601 | F10: 9072.7727
A11: Connecticut Sun | B11: 22 | C11: 6848 | D11: 19156 | E11: 190369 | F11: 8653.1364
A12: Dallas Wings | B12: 22 | C12: 5228 | D12: 20409 | E12: 159998 | F12: 7272.6364
A13: Washington Mystics | B13: 22 | C13: 4200 | D13: 11183 | E13: 116666 | F13: 5303
A14: Atlanta Dream | B14: 24 | C14: 3265 | D14: 17044 | E14: 106160 | F14: 4423.3333

Sheet team_market
A1: arena | B1: team | C1: capacity | D1: msa
A2: Target Center | B2: Minnesota Lynx | C2: 20000 | D2: Minneapolis-St. Paul-Bloomington, MN-WI
A3: Crypto.com Arena | B3: Los Angeles Sparks | C3: 19079 | D3: Los Angeles-Long Beach-Anaheim, CA
A4: Climate Pledge Arena | B4: Seattle Storm | C4: 18300 | D4: Seattle-Tacoma-Bellevue, WA
A5: Chase Center | B5: Golden State Valkyries | C5: 18064 | D5: San Francisco-Oakland-Fremont, CA
A6: Gainbridge Fieldhouse | B6: Indiana Fever | C6: 18000 | D6: Indianapolis-Carmel-Greenwood, IN
A7: Barclays Center | B7: New York Liberty | C7: 17732 | D7: New York-Newark-Jersey City, NY-NJ
A8: PHX Arena | B8: Phoenix Mercury | C8: 17071 | D8: Phoenix-Mesa-Chandler, AZ
A9: Michelob Ultra Arena | B9: Las Vegas Aces | C9: 12000 | D9: Las Vegas-Henderson-North Las Vegas, NV
A10: Wintrust Arena | B10: Chicago Sky | C10: 10387 | D10: Chicago-Naperville-Elgin, IL-IN
A11: Mohegan Sun Arena | B11: Connecticut Sun | C11: 9323 | D11: Hartford-East Hartford-Middletown, CT
A12: College Park Center | B12: Dallas Wings | C12: 7000 | D12: Dallas-Fort Worth-Arlington, TX
A13: CareFirst Arena | B13: Washington Mystics | C13: 4200 | D13: Washington-Arlington-Alexandria, DC-VA-MD-WV
A14: Gateway Center Arena | B14: Atlanta Dream | C14: 3500 | D14: Atlanta-Sandy Springs-Roswell, GA

Sheet market_demographics
A1: msa | B1: pop_total | C1: pop_female_18_44 | D1: pop_18_34 | E1: pct_black | F1: pct_hispanic | G1: median_income
A2: Minneapolis-St. Paul-Bloomington, MN-WI | B2: =_xlfn.XLOOKUP(A2,sex_age!B$1:OD$1,sex_age!B$2:OD$2) -> 3713668 | C2: =_xlfn.XLOOKUP(A2,sex_age!$B$1:$OD$1,sex_age!$B$27:$OD$27) -> 1861679 | D2: =SUM(_xlfn.XLOOKUP(A2,sex_age!$B$1:$OD$1,sex_age!$B$32:$OD$32),_xlfn.XLOOKUP(A2,sex_age!$B$1:$OD$1,sex_age!$B$33:$OD$33),_xlfn.XLOOKUP(A2,sex_age!$B$1:$OD$1,sex_age!$B$34:$OD$34),_xlfn.XLOOKUP(A2,sex_age!$B$1:$OD$1,sex_age!$B$35:$OD$35),_xlfn.XLOOKUP(A2,sex_age!$B$1:$OD$1,sex_age!$B$36:$OD$36),_xlfn.XLOOKUP(A2,sex_age!$B$1:$OD$1,sex_age!$B$37:$OD$37)) -> 406865 | E2: =(_xlfn.XLOOKUP(A2,race!$B$1:$OD$1,race!$B$4:$OD$4))/B2 -> 0.091683209 | F2: =(_xlfn.XLOOKUP(A2,hispanic!$B$1:$OD$1,hispanic!$B$4:$OD$4))/B2 -> 0.068313053 | G2: =_xlfn.XLOOKUP(A2,income!B$1:OD$1,income!B$2:OD$2) -> 99833
A3: Los Angeles-Long Beach-Anaheim, CA | B3: =_xlfn.XLOOKUP(A3,sex_age!B$1:OD$1,sex_age!B$2:OD$2) -> 12974487 | C3: =_xlfn.XLOOKUP(A3,sex_age!B$1:OD$1,sex_age!B$27:OD$27) -> 6548438 | D3: =SUM(_xlfn.XLOOKUP(A3,sex_age!$B$1:$OD$1,sex_age!$B$32:$OD$32),_xlfn.XLOOKUP(A3,sex_age!$B$1:$OD$1,sex_age!$B$33:$OD$33),_xlfn.XLOOKUP(A3,sex_age!$B$1:$OD$1,sex_age!$B$34:$OD$34),_xlfn.XLOOKUP(A3,sex_age!$B$1:$OD$1,sex_age!$B$35:$OD$35),_xlfn.XLOOKUP(A3,sex_age!$B$1:$OD$1,sex_age!$B$36:$OD$36),_xlfn.XLOOKUP(A3,sex_age!$B$1:$OD$1,sex_age!$B$37:$OD$37)) -> 1557498 | E3: =(_xlfn.XLOOKUP(A3,race!$B$1:$OD$1,race!$B$4:$OD$4))/B3 -> 0.061899326 | F3: =(_xlfn.XLOOKUP(A3,hispanic!$B$1:$OD$1,hispanic!$B$4:$OD$4))/B3 -> 0.44974456 | G3: =_xlfn.XLOOKUP(A3,income!B$1:OD$1,income!B$2:OD$2) -> 95958
A4: Seattle-Tacoma-Bellevue, WA | B4: =_xlfn.XLOOKUP(A4,sex_age!B$1:OD$1,sex_age!B$2:OD$2) -> 4061920 | C4: =_xlfn.XLOOKUP(A4,sex_age!B$1:OD$1,sex_age!B$27:OD$27) -> 2009740 | D4: =SUM(_xlfn.XLOOKUP(A4,sex_age!$B$1:$OD$1,sex_age!$B$32:$OD$32),_xlfn.XLOOKUP(A4,sex_age!$B$1:$OD$1,sex_age!$B$33:$OD$33),_xlfn.XLOOKUP(A4,sex_age!$B$1:$OD$1,sex_age!$B$34:$OD$34),_xlfn.XLOOKUP(A4,sex_age!$B$1:$OD$1,sex_age!$B$35:$OD$35),_xlfn.XLOOKUP(A4,sex_age!$B$1:$OD$1,sex_age!$B$36:$OD$36),_xlfn.XLOOKUP(A4,sex_age!$B$1:$OD$1,sex_age!$B$37:$OD$37)) -> 487121 | E4: =(_xlfn.XLOOKUP(A4,race!$B$1:$OD$1,race!$B$4:$OD$4))/B4 -> 0.061562266 | F4: =(_xlfn.XLOOKUP(A4,hispanic!$B$1:$OD$1,hispanic!$B$4:$OD$4))/B4 -> 0.11665247 | G4: =_xlfn.XLOOKUP(A4,income!B$1:OD$1,income!B$2:OD$2) -> 115177
A5: San Francisco-Oakland-Fremont, CA | B5: =_xlfn.XLOOKUP(A5,sex_age!B$1:OD$1,sex_age!B$2:OD$2) -> 4645029 | C5: =_xlfn.XLOOKUP(A5,sex_age!B$1:OD$1,sex_age!B$27:OD$27) -> 2330281 | D5: =SUM(_xlfn.XLOOKUP(A5,sex_age!$B$1:$OD$1,sex_age!$B$32:$OD$32),_xlfn.XLOOKUP(A5,sex_age!$B$1:$OD$1,sex_age!$B$33:$OD$33),_xlfn.XLOOKUP(A5,sex_age!$B$1:$OD$1,sex_age!$B$34:$OD$34),_xlfn.XLOOKUP(A5,sex_age!$B$1:$OD$1,sex_age!$B$35:$OD$35),_xlfn.XLOOKUP(A5,sex_age!$B$1:$OD$1,sex_age!$B$36:$OD$36),_xlfn.XLOOKUP(A5,sex_age!$B$1:$OD$1,sex_age!$B$37:$OD$37)) -> 515818 | E5: =(_xlfn.XLOOKUP(A5,race!$B$1:$OD$1,race!$B$4:$OD$4))/B5 -> 0.068411198 | F5: =(_xlfn.XLOOKUP(A5,hispanic!$B$1:$OD$1,hispanic!$B$4:$OD$4))/B5 -> 0.23200673 | G5: =_xlfn.XLOOKUP(A5,income!B$1:OD$1,income!B$2:OD$2) -> 136027
A6: Indianapolis-Carmel-Greenwood, IN | B6: =_xlfn.XLOOKUP(A6,sex_age!B$1:OD$1,sex_age!B$2:OD$2) -> 2130055 | C6: =_xlfn.XLOOKUP(A6,sex_age!B$1:OD$1,sex_age!B$27:OD$27) -> 1083136 | D6: =SUM(_xlfn.XLOOKUP(A6,sex_age!$B$1:$OD$1,sex_age!$B$32:$OD$32),_xlfn.XLOOKUP(A6,sex_age!$B$1:$OD$1,sex_age!$B$33:$OD$33),_xlfn.XLOOKUP(A6,sex_age!$B$1:$OD$1,sex_age!$B$34:$OD$34),_xlfn.XLOOKUP(A6,sex_age!$B$1:$OD$1,sex_age!$B$35:$OD$35),_xlfn.XLOOKUP(A6,sex_age!$B$1:$OD$1,sex_age!$B$36:$OD$36),_xlfn.XLOOKUP(A6,sex_age!$B$1:$OD$1,sex_age!$B$37:$OD$37)) -> 244296 | E6: =(_xlfn.XLOOKUP(A6,race!$B$1:$OD$1,race!$B$4:$OD$4))/B6 -> 0.15152332 | F6: =(_xlfn.XLOOKUP(A6,hispanic!$B$1:$OD$1,hispanic!$B$4:$OD$4))/B6 -> 0.08907047 | G6: =_xlfn.XLOOKUP(A6,income!B$1:OD$1,income!B$2:OD$2) -> 79852
A7: New York-Newark-Jersey City, NY-NJ | B7: =_xlfn.XLOOKUP(A7,sex_age!B$1:OD$1,sex_age!B$2:OD$2) -> 19798537 | C7: =_xlfn.XLOOKUP(A7,sex_age!B$1:OD$1,sex_age!B$27:OD$27) -> 10150843 | D7: =SUM(_xlfn.XLOOKUP(A7,sex_age!$B$1:$OD$1,sex_age!$B$32:$OD$32),_xlfn.XLOOKUP(A7,sex_age!$B$1:$OD$1,sex_age!$B$33:$OD$33),_xlfn.XLOOKUP(A7,sex_age!$B$1:$OD$1,sex_age!$B$34:$OD$34),_xlfn.XLOOKUP(A7,sex_age!$B$1:$OD$1,sex_age!$B$35:$OD$35),_xlfn.XLOOKUP(A7,sex_age!$B$1:$OD$1,sex_age!$B$36:$OD$36),_xlfn.XLOOKUP(A7,sex_age!$B$1:$OD$1,sex_age!$B$37:$OD$37)) -> 2253896 | E7: =(_xlfn.XLOOKUP(A7,race!$B$1:$OD$1,race!$B$4:$OD$4))/B7 -> 0.15841575 | F7: =(_xlfn.XLOOKUP(A7,hispanic!$B$1:$OD$1,hispanic!$B$4:$OD$4))/B7 -> 0.25709157 | G7: =_xlfn.XLOOKUP(A7,income!B$1:OD$1,income!B$2:OD$2) -> 99155
A8: Phoenix-Mesa-Chandler, AZ | B8: =_xlfn.XLOOKUP(A8,sex_age!B$1:OD$1,sex_age!B$2:OD$2) -> 5028754 | C8: =_xlfn.XLOOKUP(A8,sex_age!B$1:OD$1,sex_age!B$27:OD$27) -> 2518021 | D8: =SUM(_xlfn.XLOOKUP(A8,sex_age!$B$1:$OD$1,sex_age!$B$32:$OD$32),_xlfn.XLOOKUP(A8,sex_age!$B$1:$OD$1,sex_age!$B$33:$OD$33),_xlfn.XLOOKUP(A8,sex_age!$B$1:$OD$1,sex_age!$B$34:$OD$34),_xlfn.XLOOKUP(A8,sex_age!$B$1:$OD$1,sex_age!$B$35:$OD$35),_xlfn.XLOOKUP(A8,sex_age!$B$1:$OD$1,sex_age!$B$36:$OD$36),_xlfn.XLOOKUP(A8,sex_age!$B$1:$OD$1,sex_age!$B$37:$OD$37)) -> 575795 | E8: =(_xlfn.XLOOKUP(A8,race!$B$1:$OD$1,race!$B$4:$OD$4))/B8 -> 0.056570673 | F8: =(_xlfn.XLOOKUP(A8,hispanic!$B$1:$OD$1,hispanic!$B$4:$OD$4))/B8 -> 0.31065946 | G8: =_xlfn.XLOOKUP(A8,income!B$1:OD$1,income!B$2:OD$2) -> 88301
A9: Las Vegas-Henderson-North Las Vegas, NV | B9: =_xlfn.XLOOKUP(A9,sex_age!B$1:OD$1,sex_age!B$2:OD$2) -> 2329548 | C9: =_xlfn.XLOOKUP(A9,sex_age!B$1:OD$1,sex_age!B$27:OD$27) -> 1163836 | D9: =SUM(_xlfn.XLOOKUP(A9,sex_age!$B$1:$OD$1,sex_age!$B$32:$OD$32),_xlfn.XLOOKUP(A9,sex_age!$B$1:$OD$1,sex_age!$B$33:$OD$33),_xlfn.XLOOKUP(A9,sex_age!$B$1:$OD$1,sex_age!$B$34:$OD$34),_xlfn.XLOOKUP(A9,sex_age!$B$1:$OD$1,sex_age!$B$35:$OD$35),_xlfn.XLOOKUP(A9,sex_age!$B$1:$OD$1,sex_age!$B$36:$OD$36),_xlfn.XLOOKUP(A9,sex_age!$B$1:$OD$1,sex_age!$B$37:$OD$37)) -> 260368 | E9: =(_xlfn.XLOOKUP(A9,race!$B$1:$OD$1,race!$B$4:$OD$4))/B9 -> 0.12026496 | F9: =(_xlfn.XLOOKUP(A9,hispanic!$B$1:$OD$1,hispanic!$B$4:$OD$4))/B9 -> 0.31854892 | G9: =_xlfn.XLOOKUP(A9,income!B$1:OD$1,income!B$2:OD$2) -> 76472
A10: Chicago-Naperville-Elgin, IL-IN | B10: =_xlfn.XLOOKUP(A10,sex_age!B$1:OD$1,sex_age!B$2:OD$2) -> 9371595 | C10: =_xlfn.XLOOKUP(A10,sex_age!B$1:OD$1,sex_age!B$27:OD$27) -> 4757901 | D10: =SUM(_xlfn.XLOOKUP(A10,sex_age!$B$1:$OD$1,sex_age!$B$32:$OD$32),_xlfn.XLOOKUP(A10,sex_age!$B$1:$OD$1,sex_age!$B$33:$OD$33),_xlfn.XLOOKUP(A10,sex_age!$B$1:$OD$1,sex_age!$B$34:$OD$34),_xlfn.XLOOKUP(A10,sex_age!$B$1:$OD$1,sex_age!$B$35:$OD$35),_xlfn.XLOOKUP(A10,sex_age!$B$1:$OD$1,sex_age!$B$36:$OD$36),_xlfn.XLOOKUP(A10,sex_age!$B$1:$OD$1,sex_age!$B$37:$OD$37)) -> 1070706 | E10: =(_xlfn.XLOOKUP(A10,race!$B$1:$OD$1,race!$B$4:$OD$4))/B10 -> 0.15982221 | F10: =(_xlfn.XLOOKUP(A10,hispanic!$B$1:$OD$1,hispanic!$B$4:$OD$4))/B10 -> 0.24078431 | G10: =_xlfn.XLOOKUP(A10,income!B$1:OD$1,income!B$2:OD$2) -> 90887
A11: Hartford-West Hartford-East Hartford, CT | B11: =_xlfn.XLOOKUP(A11,sex_age!B$1:OD$1,sex_age!B$2:OD$2) -> 1153112 | C11: =_xlfn.XLOOKUP(A11,sex_age!B$1:OD$1,sex_age!B$27:OD$27) -> 587506 | D11: =SUM(_xlfn.XLOOKUP(A11,sex_age!$B$1:$OD$1,sex_age!$B$32:$OD$32),_xlfn.XLOOKUP(A11,sex_age!$B$1:$OD$1,sex_age!$B$33:$OD$33),_xlfn.XLOOKUP(A11,sex_age!$B$1:$OD$1,sex_age!$B$34:$OD$34),_xlfn.XLOOKUP(A11,sex_age!$B$1:$OD$1,sex_age!$B$35:$OD$35),_xlfn.XLOOKUP(A11,sex_age!$B$1:$OD$1,sex_age!$B$36:$OD$36),_xlfn.XLOOKUP(A11,sex_age!$B$1:$OD$1,sex_age!$B$37:$OD$37)) -> 128304 | E11: =(_xlfn.XLOOKUP(A11,race!$B$1:$OD$1,race!$B$4:$OD$4))/B11 -> 0.11306187 | F11: =(_xlfn.XLOOKUP(A11,hispanic!$B$1:$OD$1,hispanic!$B$4:$OD$4))/B11 -> 0.16176659 | G11: =_xlfn.XLOOKUP(A11,income!B$1:OD$1,income!B$2:OD$2) -> 95118
A12: Dallas-Fort Worth-Arlington, TX | B12: =_xlfn.XLOOKUP(A12,sex_age!B$1:OD$1,sex_age!B$2:OD$2) -> 7985590 | C12: =_xlfn.XLOOKUP(A12,sex_age!B$1:OD$1,sex_age!B$27:OD$27) -> 4031384 | D12: =SUM(_xlfn.XLOOKUP(A12,sex_age!$B$1:$OD$1,sex_age!$B$32:$OD$32),_xlfn.XLOOKUP(A12,sex_age!$B$1:$OD$1,sex_age!$B$33:$OD$33),_xlfn.XLOOKUP(A12,sex_age!$B$1:$OD$1,sex_age!$B$34:$OD$34),_xlfn.XLOOKUP(A12,sex_age!$B$1:$OD$1,sex_age!$B$35:$OD$35),_xlfn.XLOOKUP(A12,sex_age!$B$1:$OD$1,sex_age!$B$36:$OD$36),_xlfn.XLOOKUP(A12,sex_age!$B$1:$OD$1,sex_age!$B$37:$OD$37)) -> 961263 | E12: =(_xlfn.XLOOKUP(A12,race!$B$1:$OD$1,race!$B$4:$OD$4))/B12 -> 0.16310091 | F12: =(_xlfn.XLOOKUP(A12,hispanic!$B$1:$OD$1,hispanic!$B$4:$OD$4))/B12 -> 0.29691632 | G12: =_xlfn.XLOOKUP(A12,income!B$1:OD$1,income!B$2:OD$2) -> 90275
A13: Washington-Arlington-Alexandria, DC-VA-MD-WV | B13: =_xlfn.XLOOKUP(A13,sex_age!B$1:OD$1,sex_age!B$2:OD$2) -> 6318377 | C13: =_xlfn.XLOOKUP(A13,sex_age!B$1:OD$1,sex_age!B$27:OD$27) -> 3210855 | D13: =SUM(_xlfn.XLOOKUP(A13,sex_age!$B$1:$OD$1,sex_age!$B$32:$OD$32),_xlfn.XLOOKUP(A13,sex_age!$B$1:$OD$1,sex_age!$B$33:$OD$33),_xlfn.XLOOKUP(A13,sex_age!$B$1:$OD$1,sex_age!$B$34:$OD$34),_xlfn.XLOOKUP(A13,sex_age!$B$1:$OD$1,sex_age!$B$35:$OD$35),_xlfn.XLOOKUP(A13,sex_age!$B$1:$OD$1,sex_age!$B$36:$OD$36),_xlfn.XLOOKUP(A13,sex_age!$B$1:$OD$1,sex_age!$B$37:$OD$37)) -> 721366 | E13: =(_xlfn.XLOOKUP(A13,race!$B$1:$OD$1,race!$B$4:$OD$4))/B13 -> 0.24574729 | F13: =(_xlfn.XLOOKUP(A13,hispanic!$B$1:$OD$1,hispanic!$B$4:$OD$4))/B13 -> 0.18036974 | G13: =_xlfn.XLOOKUP(A13,income!B$1:OD$1,income!B$2:OD$2) -> 126684
A14: Atlanta-Sandy Springs-Roswell, GA | B14: =_xlfn.XLOOKUP(A14,sex_age!B$1:OD$1,sex_age!B$2:OD$2) -> 6256377 | C14: =_xlfn.XLOOKUP(A14,sex_age!B$1:OD$1,sex_age!B$27:OD$27) -> 3220306 | D14: =SUM(_xlfn.XLOOKUP(A14,sex_age!$B$1:$OD$1,sex_age!$B$32:$OD$32),_xlfn.XLOOKUP(A14,sex_age!$B$1:$OD$1,sex_age!$B$33:$OD$33),_xlfn.XLOOKUP(A14,sex_age!$B$1:$OD$1,sex_age!$B$34:$OD$34),_xlfn.XLOOKUP(A14,sex_age!$B$1:$OD$1,sex_age!$B$35:$OD$35),_xlfn.XLOOKUP(A14,sex_age!$B$1:$OD$1,sex_age!$B$36:$OD$36),_xlfn.XLOOKUP(A14,sex_age!$B$1:$OD$1,sex_age!$B$37:$OD$37)) -> 737974 | E14: =(_xlfn.XLOOKUP(A14,race!$B$1:$OD$1,race!$B$4:$OD$4))/B14 -> 0.33699855 | F14: =(_xlfn.XLOOKUP(A14,hispanic!$B$1:$OD$1,hispanic!$B$4:$OD$4))/B14 -> 0.12423436 | G14: =_xlfn.XLOOKUP(A14,income!B$1:OD$1,income!B$2:OD$2) -> 89724

Sheet missed_revenue_opportunity
A1: market_msa | B1: interest_norm | C1: income_norm | D1: conversion_gap | E1: missed_revenue_score
A2: Las Vegas-Henderson-North Las Vegas, NV | B2: 0.60965565 | C2: 0.56218251 | D2: -0.2645235 | E2: -0.090662187
A3: Phoenix-Mesa-Chandler, AZ | B3: 0.23142312 | C3: 0.64914318 | D3: -0.34490621 | E3: -0.051814136
A4: Atlanta-Sandy Springs-Roswell, GA | B4: 0.22789308 | C4: 0.65960434 | D4: 0.21615363 | E4: 0.032492055
A5: Indianapolis-Carmel-Greenwood, IN | B5: 1 | C5: 0.58703052 | D5: -0.46427428 | E5: -0.27254317
A6: New York-Newark-Jersey City, NY-NJ | B6: 0.1214106 | C6: 0.72893617 | D6: 0.095749259 | E6: 0.0084738649
A7: Dallas-Fort Worth-Arlington, TX | B7: 0.19338283 | C7: 0.66365501 | D7: 0.056930923 | E7: 0.0073064851
A8: Los Angeles-Long Beach-Anaheim, CA | B8: 0.1483513 | C8: 0.70543348 | D8: -0.15068878 | E8: -0.015769878
A9: San Francisco-Oakland-Fremont, CA | B9: 0.35772743 | C9: 1 | D9: -0.47176746 | E9: -0.16876416
A10: Minneapolis-St. Paul-Bloomington, MN-WI | B10: 0.37778739 | C10: 0.73392047 | D10: -0.15645164 | E10: -0.043378706
A11: Chicago-Naperville-Elgin, IL-IN | B11: 0.24129731 | C11: 0.66815412 | D11: 0.1297947 | E11: 0.020925994
A12: Washington-Arlington-Alexandria, DC-VA-MD-WV | B12: 0.21201003 | C12: 0.93131511 | D12: 0.080309005 | E12: 0.015856864

Sheet conversion_gap
A1: market_msa | B1: Team | C1: interest_norm | D1: attendance_norm | E1: conversion_gap
A2: Indianapolis-Carmel-Greenwood, IN | B2: Indiana Fever | C2: 0.45038423 | D2: 0.91465851 | E2: -0.46427428
A3: Minneapolis-St. Paul-Bloomington, MN-WI | B3: Minnesota Lynx | C3: 0.39391914 | D3: 0.55037079 | E3: -0.15645164
A4: New York-Newark-Jersey City, NY-NJ | B4: New York Liberty | C4: 1 | D4: 0.90425074 | E4: 0.095749259
A5: Las Vegas-Henderson-North Las Vegas, NV | B5: Las Vegas Aces | C5: 0.3591714 | D5: 0.6236949 | E5: -0.2645235
A6: Phoenix-Mesa-Chandler, AZ | B6: Phoenix Mercury | C6: 0.32442366 | D6: 0.66932987 | E6: -0.34490621
A7: Chicago-Naperville-Elgin, IL-IN | B7: Chicago Sky | C7: 0.63147344 | D7: 0.50167874 | E7: 0.1297947
A8: Atlanta-Sandy Springs-Roswell, GA | B8: Atlanta Dream | C8: 0.46074173 | D8: 0.2445881 | E8: 0.21615363
A9: Dallas-Fort Worth-Arlington, TX | B9: Dallas Wings | C9: 0.45907117 | D9: 0.40214024 | E9: 0.056930923
A10: Washington-Arlington-Alexandria, DC-VA-MD-WV | B10: Washington Mystics | C10: 0.37353826 | D10: 0.29322925 | E10: 0.080309005
A11: Los Angeles-Long Beach-Anaheim, CA | B11: Los Angeles Sparks | C11: 0.53725359 | D11: 0.68794237 | E11: -0.15068878
A12: San Francisco-Oakland-Fremont, CA | B12: Golden State Valkyries | C12: 0.52823254 | D12: 1 | E12: -0.47176746

Sheet combined_trends_wnba
A1: Week | B1: indiana | C1: california | D1: california2 | E1: new_york | F1: texas | G1: arizona | H1: connecticut | I1: georgia | J1: illinois | K1: minnesota | L1: nevada | M1: washington | N1: district_of_columbia
A2: 45739 | B2: 6 | C2: 3 | D2: 3 | E2: 4 | F2: 3 | G2: 3 | H2: 6 | I2: 3 | J2: 4 | K2: 4 | L2: 2 | M2: 4 | N2: 7
A3: 45746 | B3: 5 | C3: 3 | D3: 3 | E3: 4 | F3: 3 | G3: 3 | H3: 7 | I3: 4 | J3: 4 | K3: 5 | L3: 4 | M3: 5 | N3: 7
A4: 45753 | B4: 8 | C4: 4 | D4: 4 | E4: 6 | F4: 5 | G4: 5 | H4: 16 | I4: 5 | J4: 7 | K4: 8 | L4: 4 | M4: 8 | N4: 11
A5: 45760 | B5: 26 | C5: 13 | D5: 13 | E5: 18 | F5: 15 | G5: 12 | H5: 48 | I5: 16 | J5: 23 | K5: 25 | L5: 12 | M5: 22 | N5: 32
A6: 45767 | B6: 4 | C6: 3 | D6: 3 | E6: 3 | F6: 3 | G6: 2 | H6: 5 | I6: 3 | J6: 3 | K6: 3 | L6: 3 | M6: 3 | N6: 5
A7: 45774 | B7: 11 | C7: 4 | D7: 4 | E7: 5 | F7: 4 | G7: 4 | H7: 9 | I7: 5 | J7: 6 | K7: 6 | L7: 6 | M7: 6 | N7: 9
A8: 45781 | B8: 13 | C8: 7 | D8: 7 | E8: 7 | F8: 6 | G8: 8 | H8: 12 | I8: 8 | J8: 9 | K8: 8 | L8: 11 | M8: 9 | N8: 13
A9: 45788 | B9: 20 | C9: 13 | D9: 13 | E9: 13 | F9: 12 | G9: 13 | H9: 20 | I9: 14 | J9: 16 | K9: 16 | L9: 14 | M9: 14 | N9: 17
A10: 45795 | B10: 40 | C10: 23 | D10: 23 | E10: 22 | F10: 20 | G10: 24 | H10: 29 | I10: 27 | J10: 29 | K10: 27 | L10: 24 | M10: 22 | N10: 34
A11: 45802 | B11: 25 | C11: 15 | D11: 15 | E11: 17 | F11: 15 | G11: 22 | H11: 26 | I11: 21 | J11: 22 | K11: 22 | L11: 22 | M11: 21 | N11: 28
A12: 45809 | B12: 22 | C12: 13 | D12: 13 | E12: 14 | F12: 13 | G12: 18 | H12: 20 | I12: 17 | J12: 18 | K12: 20 | L12: 18 | M12: 14 | N12: 21
A13: 45816 | B13: 27 | C13: 12 | D13: 12 | E13: 16 | F13: 14 | G13: 18 | H13: 22 | I13: 19 | J13: 20 | K13: 24 | L13: 21 | M13: 17 | N13: 21
... A53: 46096 | B53: 7 | C53: 4 | D53: 4 | E53: 5 | F53: 4 | G53: 4 | H53: 6 | I53: 4 | J53: 5 | K53: 5 | L53: 5 | M53: 5 | N53: 10

Sheet interest_proxies
A1: Week | B1: market_msa | C1: interest_league | D1: interest_team | E1: interest_player | F1: pop_total | G1: median_income
A2: 45739 | B2: Indianapolis-Carmel-Greenwood, IN | C2: 6 | D2: 6 | E2: 19 | F2: 2130055 | G2: 79852
A3: 45739 | B3: Minneapolis-St. Paul-Bloomington, MN-WI | C3: 4 | D3: 6 | E3: 0 | F3: 3713668 | G3: 99833
A4: 45739 | B4: New York-Newark-Jersey City, NY-NJ | C4: 4 | D4: 49 | E4: 11 | F4: 19798537 | G4: 99155
A5: 45739 | B5: Las Vegas-Henderson-North Las Vegas, NV | C5: 2 | D5: 5 | E5: 0 | F5: 2329548 | G5: 76472
A6: 45739 | B6: Phoenix-Mesa-Chandler, AZ | C6: 3 | D6: 4 | E6: 0 | F6: 5028754 | G6: 88301
A7: 45739 | B7: Chicago-Naperville-Elgin, IL-IN | C7: 4 | D7: 25 | E7: 35 | F7: 9371595 | G7: 90887
A8: 45739 | B8: Atlanta-Sandy Springs-Roswell, GA | C8: 3 | D8: 13 | E8: 0 | F8: 6256377 | G8: 89724
A9: 45739 | B9: Dallas-Fort Worth-Arlington, TX | C9: 3 | D9: 13 | E9: 28 | F9: 7985590 | G9: 90275
A10: 45739 | B10: Washington-Arlington-Alexandria, DC-VA-MD-WV | C10: 4 | D10: 100 | E10: 0 | F10: 6318377 | G10: 126684
A11: 45739 | B11: Los Angeles-Long Beach-Anaheim, CA | C11: 3 | D11: 0 | E11: 32 | F11: 12974487 | G11: 95958
A12: 45739 | B12: San Francisco-Oakland-Fremont, CA | C12: 3 | D12: 15 | E12: 0 | F12: 4645029 | G12: 136027
A13: 45746 | B13: Indianapolis-Carmel-Greenwood, IN | C13: 5 | D13: 5 | E13: 14 | F13: 2130055 | G13: 79852
... A573: 46096 | B573: San Francisco-Oakland-Fremont, CA | C573: 4 | D573: 6 | E573: 3 | F573: 4645029 | G573: 136027

Sheet sex_age
A1: se | B1: Abilene, TX | C1: Aguadilla, PR | D1: Akron, OH | E1: Albany, GA | F1: Albany, OR | G1: Albany-Schenectady-Troy, NY | H1: Albuquerque, NM | I1: Alexandria, LA | J1: Allentown-Bethlehem-Easton, PA-NJ | K1: Altoona, PA | L1: Amarillo, TX | M1: Ames, IA | N1: Amherst Town-Northampton, MA | O1: Anchorage, AK | P1: Ann Arbor, MI | Q1: Anniston-Oxford, AL | R1: Appleton, WI | S1: Arecibo, PR | T1: Asheville, NC | U1: Athens-Clarke County, GA | V1: Atlanta-Sandy Springs-Roswell, GA | W1: Atlantic City-Hammonton, NJ | X1: Auburn-Opelika, AL | Y1: Augusta-Richmond County, GA-SC | Z1: Austin-Round Rock-San Marcos, TX | AA1: Bakersfield-Delano, CA | AB1: Baltimore-Columbia-Towson, MD | AC1: Bangor, ME | AD1: Barnstable Town, MA | AE1: Baton Rouge, LA | AF1: Battle Creek, MI | AG1: Bay City, MI | AH1: Beaumont-Port Arthur, TX | AI1: Beckley, WV | AJ1: Bellingham, WA | AK1: Bend, OR | AL1: Billings, MT | AM1: Binghamton, NY | AN1: Birmingham, AL | AO1: Bismarck, ND | AP1: Blacksburg-Christiansburg-Radford, VA | AQ1: Bloomington, IL | AR1: Bloomington, IN | AS1: Boise City, ID | AT1: Boston-Cambridge-Newton, MA-NH | AU1: Boulder, CO | AV1: Bowling Green, KY | AW1: Bozeman, MT | AX1: Bremerton-Silverdale-Port Orchard, WA | AY1: Bridgeport-Stamford-Danbury, CT | AZ1: Brownsville-Harlingen, TX | BA1: Brunswick-St. Simons, GA | BB1: Buffalo-Cheektowaga, NY | BC1: Burlington, NC | BD1: Burlington-South Burlington, VT | BE1: Canton-Massillon, OH | BF1: Cape Coral-Fort Myers, FL | BG1: Cape Girardeau, MO-IL | BH1: Carson City, NV | BI1: Casper, WY | BJ1: Cedar Rapids, IA | BK1: Chambersburg, PA | BL1: Champaign-Urbana, IL | BM1: Charleston, WV | BN1: Charleston-North Charleston, SC | BO1: Charlotte-Concord-Gastonia, NC-SC | BP1: Charlottesville, VA | BQ1: Chattanooga, TN-GA | BR1: Cheyenne, WY | BS1: Chicago-Naperville-Elgin, IL-IN | BT1: Chico, CA | BU1: Cincinnati, OH-KY-IN | BV1: Clarksville, TN-KY | BW1: Cleveland, OH | BX1: Cleveland, TN | BY1: Coeur d'Alene, ID | BZ1: College Station-Bryan, TX | CA1: Colorado Springs, CO | CB1: Columbia, MO | CC1: Columbia, SC | CD1: Columbus, GA-AL | CE1: Columbus, IN | CF1: Columbus, OH | CG1: Corpus Christi, TX | CH1: Corvallis, OR | CI1: Crestview-Fort Walton Beach-Destin, FL | CJ1: Dallas-Fort Worth-Arlington, TX | CK1: Dalton, GA | CL1: Daphne-Fairhope-Foley, AL | CM1: Davenport-Moline-Rock Island, IA-IL | CN1: Dayton-Kettering-Beavercreek, OH | CO1: Decatur, AL | CP1: Decatur, IL | CQ1: Deltona-Daytona Beach-Ormond Beach, FL | CR1: Denver-Aurora-Centennial, CO | CS1: Des Moines-West Des Moines, IA | CT1: Detroit-Warren-Dearborn, MI | CU1: Dothan, AL | CV1: Dover, DE | CW1: Dubuque, IA | CX1: Duluth, MN-WI | CY1: Durham-Chapel Hill, NC | CZ1: Eagle Pass, TX | DA1: Eau Claire, WI | DB1: El Centro, CA | DC1: Elizabethtown, KY | DD1: Elkhart-Goshen, IN | DE1: Elmira, NY | DF1: El Paso, TX | DG1: Enid, OK | DH1: Erie, PA | DI1: Eugene-Springfield, OR | DJ1: Evansville, IN | DK1: Fairbanks-College, AK | DL1: Fargo, ND-MN | DM1: Farmington, NM | DN1: Fayetteville, NC | DO1: Fayetteville-Springdale-Rogers, AR | DP1: Flagstaff, AZ | DQ1: Flint, MI | DR1: Florence, SC | DS1: Florence-Muscle Shoals, AL | DT1: Fond du Lac, WI | DU1: Fort Collins-Loveland, CO | DV1: Fort Smith, AR-OK | DW1: Fort Wayne, IN | DX1: Fresno, CA | DY1: Gadsden, AL | DZ1: Gainesville, FL | EA1: Gainesville, GA | EB1: Gettysburg, PA | EC1: Glens Falls, NY | ED1: Goldsboro, NC | EE1: Grand Forks, ND-MN | EF1: Grand Island, NE | EG1: Grand Junction, CO | EH1: Grand Rapids-Wyoming-Kentwood, MI | EI1: Grants Pass, OR | EJ1: Great Falls, MT | EK1: Greeley, CO | EL1: Green Bay, WI | EM1: Greensboro-High Point, NC | EN1: Greenville, NC | EO1: Greenville-Anderson-Greer, SC | EP1: Guayama, PR | EQ1: Gulfport-Biloxi, MS | ER1: Hagerstown-Martinsburg, MD-WV | ES1: Hammond, LA | ET1: Hanford-Corcoran, CA | EU1: Harrisburg-Carlisle, PA | EV1: Harrisonburg, VA | EW1: Hartford-West Hartford-East Hartford, CT | EX1: Hattiesburg, MS | EY1: Helena, MT | EZ1: Hickory-Lenoir-Morganton, NC | FA1: Hilton Head Island-Bluffton-Port Royal, SC | FB1: Hinesville, GA | FC1: Homosassa Springs, FL | FD1: Hot Springs, AR | FE1: Houma-Bayou Cane-Thibodaux, LA | FF1: Houston-Pasadena-The Woodlands, TX | FG1: Huntington-Ashland, WV-KY-OH | FH1: Huntsville, AL | FI1: Idaho Falls, ID | FJ1: Indianapolis-Carmel-Greenwood, IN | FK1: Iowa City, IA | FL1: Ithaca, NY | FM1: Jackson, MI | FN1: Jackson, MS | FO1: Jackson, TN | FP1: Jacksonville, FL | FQ1: Jacksonville, NC | FR1: Janesville-Beloit, WI | FS1: Jefferson City, MO | FT1: Johnson City, TN | FU1: Johnstown, PA | FV1: Jonesboro, AR | FW1: Joplin, MO-KS | FX1: Kahului-Wailuku, HI | FY1: Kalamazoo-Portage, MI | FZ1: Kankakee, IL | GA1: Kansas City, MO-KS | GB1: Kennewick-Richland, WA | GC1: Kenosha, WI | GD1: Killeen-Temple, TX | GE1: Kingsport-Bristol, TN-VA | GF1: Kingston, NY | GG1: Kiryas Joel-Poughkeepsie-Newburgh, NY | GH1: Knoxville, TN | GI1: Kokomo, IN | GJ1: La Crosse-Onalaska, WI-MN | GK1: Lafayette, LA | GL1: Lafayette-West Lafayette, IN | GM1: Lake Charles, LA | GN1: Lake Havasu City-Kingman, AZ | GO1: Lakeland-Winter Haven, FL | GP1: Lancaster, PA | GQ1: Lansing-East Lansing, MI | GR1: Laredo, TX | GS1: Las Cruces, NM | GT1: Las Vegas-Henderson-North Las Vegas, NV | GU1: Lawrence, KS | GV1: Lawton, OK | GW1: Lebanon, PA | GX1: Lewiston, ID-WA | GY1: Lewiston-Auburn, ME | GZ1: Lexington-Fayette, KY | HA1: Lexington Park, MD | HB1: Lima, OH | HC1: Lincoln, NE | HD1: Little Rock-North Little Rock-Conway, AR | HE1: Logan, UT-ID | HF1: Longview, TX | HG1: Longview-Kelso, WA | HH1: Los Angeles-Long Beach-Anaheim, CA | HI1: Louisville/Jefferson County, KY-IN | HJ1: Lubbock, TX | HK1: Lynchburg, VA | HL1: Macon-Bibb County, GA | HM1: Madison, WI | HN1: Manchester-Nashua, NH | HO1: Manhattan, KS | HP1: Mankato, MN | HQ1: Mansfield, OH | HR1: Mayagüez, PR | HS1: McAllen-Edinburg-Mission, TX | HT1: Medford, OR | HU1: Memphis, TN-MS-AR | HV1: Merced, CA | HW1: Miami-Fort Lauderdale-West Palm Beach, FL | HX1: Michigan City-La Porte, IN | HY1: Midland, MI | HZ1: Midland, TX | IA1: Milwaukee-Waukesha, WI | IB1: Minneapolis-St. Paul-Bloomington, MN-WI | IC1: Minot, ND | ID1: Missoula, MT | IE1: Mobile, AL | IF1: Modesto, CA | IG1: Monroe, LA | IH1: Monroe, MI | II1: Montgomery, AL | IJ1: Morgantown, WV | IK1: Morristown, TN | IL1: Mount Vernon-Anacortes, WA | IM1: Muncie, IN | IN1: Muskegon-Norton Shores, MI | IO1: Myrtle Beach-Conway-North Myrtle Beach, SC | IP1: Napa, CA | IQ1: Naples-Marco Island, FL | IR1: Nashville-Davidson--Murfreesboro--Franklin, TN | IS1: New Haven, CT | IT1: New Orleans-Metairie, LA | IU1: New York-Newark-Jersey City, NY-NJ | IV1: Niles, MI | IW1: North Port-Bradenton-Sarasota, FL | IX1: Norwich-New London-Willimantic, CT | IY1: Ocala, FL | IZ1: Odessa, TX | JA1: Ogden, UT | JB1: Oklahoma City, OK | JC1: Olympia-Lacey-Tumwater, WA | JD1: Omaha, NE-IA | JE1: Orlando-Kissimmee-Sanford, FL | JF1: Oshkosh-Neenah, WI | JG1: Owensboro, KY | JH1: Oxnard-Thousand Oaks-Ventura, CA | JI1: Paducah, KY-IL | JJ1: Palm Bay-Melbourne-Titusville, FL | JK1: Panama City-Panama City Beach, FL | JL1: Parkersburg-Vienna, WV | JM1: Pensacola-Ferry Pass-Brent, FL | JN1: Peoria, IL | JO1: Philadelphia-Camden-Wilmington, PA-NJ-DE-MD | JP1: Phoenix-Mesa-Chandler, AZ | JQ1: Pinehurst-Southern Pines, NC | JR1: Pittsburgh, PA | JS1: Pittsfield, MA | JT1: Pocatello, ID | JU1: Ponce, PR | JV1: Portland-South Portland, ME | JW1: Portland-Vancouver-Hillsboro, OR-WA | JX1: Port St. Lucie, FL | JY1: Prescott Valley-Prescott, AZ | JZ1: Providence-Warwick, RI-MA | KA1: Provo-Orem-Lehi, UT | KB1: Pueblo, CO | KC1: Punta Gorda, FL | KD1: Racine-Mount Pleasant, WI | KE1: Raleigh-Cary, NC | KF1: Rapid City, SD | KG1: Reading, PA | KH1: Redding, CA | KI1: Reno, NV | KJ1: Richmond, VA | KK1: Riverside-San Bernardino-Ontario, CA | KL1: Roanoke, VA | KM1: Rochester, MN | KN1: Rochester, NY | KO1: Rockford, IL | KP1: Rocky Mount, NC | KQ1: Rome, GA | KR1: Sacramento-Roseville-Folsom, CA | KS1: Saginaw, MI | KT1: St. Cloud, MN | KU1: St. George, UT | KV1: St. Joseph, MO-KS | KW1: St. Louis, MO-IL | KX1: Salem, OR | KY1: Salinas, CA | KZ1: Salisbury, MD | LA1: Salt Lake City-Murray, UT | LB1: San Angelo, TX | LC1: San Antonio-New Braunfels, TX | LD1: San Diego-Chula Vista-Carlsbad, CA | LE1: Sandusky, OH | LF1: San Francisco-Oakland-Fremont, CA | LG1: San Jose-Sunnyvale-Santa Clara, CA | LH1: San Juan-Bayamón-Caguas, PR | LI1: San Luis Obispo-Paso Robles, CA | LJ1: Santa Cruz-Watsonville, CA | LK1: Santa Fe, NM | LL1: Santa Maria-Santa Barbara, CA | LM1: Santa Rosa-Petaluma, CA | LN1: Savannah, GA | LO1: Scranton--Wilkes-Barre, PA | LP1: Seattle-Tacoma-Bellevue, WA | LQ1: Sebastian-Vero Beach-West Vero Corridor, FL | LR1: Sebring, FL | LS1: Sheboygan, WI | LT1: Sherman-Denison, TX | LU1: Shreveport-Bossier City, LA | LV1: Sierra Vista-Douglas, AZ | LW1: Sioux City, IA-NE-SD | LX1: Sioux Falls, SD-MN | LY1: Slidell-Mandeville-Covington, LA | LZ1: South Bend-Mishawaka, IN-MI | MA1: Spartanburg, SC | MB1: Spokane-Spokane Valley, WA | MC1: Springfield, IL | MD1: Springfield, MA | ME1: Springfield, MO | MF1: Springfield, OH | MG1: State College, PA | MH1: Staunton-Stuarts Draft, VA | MI1: Stockton-Lodi, CA | MJ1: Sumter, SC | MK1: Syracuse, NY | ML1: Tallahassee, FL | MM1: Tampa-St. Petersburg-Clearwater, FL | MN1: Terre Haute, IN | MO1: Texarkana, TX-AR | MP1: Toledo, OH | MQ1: Topeka, KS | MR1: Traverse City, MI | MS1: Trenton-Princeton, NJ | MT1: Tucson, AZ | MU1: Tulsa, OK | MV1: Tuscaloosa, AL | MW1: Twin Falls, ID | MX1: Tyler, TX | MY1: Urban Honolulu, HI | MZ1: Utica-Rome, NY | NA1: Valdosta, GA | NB1: Vallejo, CA | NC1: Victoria, TX | ND1: Vineland, NJ | NE1: Virginia Beach-Chesapeake-Norfolk, VA-NC | NF1: Visalia, CA | NG1: Waco, TX | NH1: Walla Walla, WA | NI1: Warner Robins, GA | NJ1: Washington-Arlington-Alexandria, DC-VA-MD-WV | NK1: Waterbury-Shelton, CT | NL1: Waterloo-Cedar Falls, IA | NM1: Watertown-Fort Drum, NY | NN1: Wausau, WI | NO1: Weirton-Steubenville, WV-OH | NP1: Wenatchee-East Wenatchee, WA | NQ1: Wheeling, WV-OH | NR1: Wichita, KS | NS1: Wichita Falls, TX | NT1: Wildwood-The Villages, FL | NU1: Williamsport, PA | NV1: Wilmington, NC | NW1: Winchester, VA-WV | NX1: Winston-Salem, NC | NY1: Worcester, MA | NZ1: Yakima, WA | OA1: York-Hanover, PA | OB1: Youngstown-Warren, OH | OC1: Yuba City, CA | OD1: Yuma, AZ
A2: Total: | B2: 180408 | C2: 251769 | D2: 699820 | E2: 146018 | F2: 130706 | G2: 906052 | H2: 921482 | I2: 149622 | J2: 873603 | K2: 121277 | L2: 271917 | M2: 127134 | N2: 162028 | O2: 401964 | P2: 369822 | Q2: 116090 | R2: 245768 | S2: 180767 | T2: 414711 | U2: 220197 | V2: 6256377 | W2: 371211 | X2: 199825 | Y2: 624181 | Z2: 2426592 | AA2: 915075 | AB2: 2849436 | AC2: 154710 | AD2: 231668 | AE2: 875313 | AF2: 133778 | AG2: 103008 | AH2: 396827 | AI2: 112714 | AJ2: 230503 | AK2: 257814 | AL2: 189255 | AM2: 245242 | AN2: 1184613 | AO2: 136216 | AP2: 181664 | AQ2: 171556 | AR2: 162569 | AS2: 811115 | AT2: 4953354 | AU2: 328961 | AV2: 186959 | AW2: 124074 | AX2: 277881 | AY2: 956330 | AZ2: 426120 | BA2: 115074 | BB2: 1161343 | BC2: 176893 | BD2: 227846 | BE2: 400372 | BF2: 817666 | BG2: 98169 | BH2: 58384 | BI2: 79977 | BJ2: 276624 | BK2: 157379 | BL2: 238842 | BM2: 205398 | BN2: 834267 | BO2: 2768407 | BP2: 224335 | BQ2: 575812 | BR2: 101060 | BS2: 9371595 | BT2: 207929 | BU2: 2270706 | BV2: 334564 | BW2: 2171526 | BX2: 128963 | BY2: 181996 | BZ2: 278335 | CA2: 767824 | CB2: 215014 | CC2: 849181 | CD2: 325615 | CE2: 83536 | CF2: 2175788 | CG2: 448012 | CH2: 96303 | CI2: 299547 | CJ2: 7985590 | CK2: 144160 | CL2: 246989 | CM2: 381503 | CN2: 816080 | CO2: 157747 | CP2: 101849 | CQ2: 706150 | CR2: 3002721 | CS2: 731120 | CT2: 4376828 | CU2: 152674 | CV2: 187604 | CW2: 99030 | CX2: 280870 | CY2: 601724 | CZ2: 58082 | DA2: 173915 | DB2: 180202 | DC2: 127049 | DD2: 207132 | DE2: 82147 | DF2: 874182 | DG2: 62146 | DH2: 269052 | DI2: 384207 | DJ2: 270494 | DK2: 95460 | DL2: 259459 | DM2: 120942 | DN2: 392380 | DO2: 577726 | DP2: 144508 | DQ2: 403305 | DR2: 199675 | DS2: 153852 | DT2: 104137 | DU2: 367368 | DV2: 229899 | DW2: 455416 | DX2: 1177665 | DY2: 103105 | DZ2: 349923 | EA2: 212705 | EB2: 106115 | EC2: 126039 | ED2: 118652 | EE2: 103628 | EF2: 76794 | EG2: 158601 | EH2: 1162152 | EI2: 88179 | EJ2: 84606 | EK2: 350396 | EL2: 331145 | EM2: 786419 | EN2: 177193 | EO2: 961939 | EP2: 66202 | EQ2: 421201 | ER2: 302649 | ES2: 136738 | ET2: 153298 | EU2: 604155 | EV2: 136992 | EW2: 1153112 | EX2: 155434 | EY2: 93906 | EZ2: 368316 | FA2: 227455 | FB2: 85771 | FC2: 162472 | FD2: 100035 | FE2: 202438 | FF2: 7442788 | FG2: 370729 | FH2: 516951 | FI2: 165361 | FJ2: 2130055 | FK2: 179200 | FL2: 104537 | FM2: 160060 | FN2: 611324 | FO2: 181719 | FP2: 1683960 | FQ2: 207906 | FR2: 164350 | FS2: 150437 | FT2: 210729 | FU2: 131538 | FV2: 135792 | FW2: 203626 | FX2: 164589 | FY2: 262375 | FZ2: 106635 | GA2: 2218142 | GB2: 311807 | GC2: 168438 | GD2: 494360 | GE2: 310842 | GF2: 182601 | GG2: 704836 | GH2: 932241 | GI2: 83752 | GJ2: 170190 | GK2: 413428 | GL2: 226805 | GM2: 244027 | GN2: 220517 | GO2: 790694 | GP2: 557931 | GQ2: 472669 | GR2: 269294 | GS2: 224266 | GT2: 2329548 | GU2: 120302 | GV2: 127310 | GW2: 144186 | GX2: 65164 | GY2: 113423 | GZ2: 522560 | HA2: 209439 | HB2: 101348 | HC2: 344337 | HD2: 758629 | HE2: 155102 | HF2: 291044 | HG2: 112360 | HH2: 12974487 | HI2: 1372558 | HJ2: 358708 | HK2: 263798 | HL2: 234943 | HM2: 691830 | HN2: 426378 | HO2: 133965 | HP2: 104282 | HQ2: 125099 | HR2: 209892 | HS2: 891977 | HT2: 222645 | HU2: 1341924 | HV2: 290201 | HW2: 6249291 | HX2: 111917 | HY2: 83757 | HZ2: 180019 | IA2: 1568938 | IB2: 3713668 | IC2: 76484 | ID2: 125631 | IE2: 412590 | IF2: 553990 | IG2: 223674 | IH2: 155505 | II2: 386024 | IJ2: 141323 | IK2: 122533 | IL2: 131328 | IM2: 112280 | IN2: 175961 | IO2: 383016 | IP2: 134869 | IQ2: 398291 | IR2: 2079596 | IS2: 570598 | IT2: 981662 | IU2: 19798537 | IV2: 153288 | IW2: 889339 | IX2: 279971 | IY2: 400078 | IZ2: 164654 | JA2: 653374 | JB2: 1463267 | JC2: 299067 | JD2: 982064 | JE2: 2793746 | JF2: 171769 | JG2: 112762 | JH2: 837469 | JI2: 102748 | JJ2: 632780 | JK2: 211922 | JL2: 88460 | JM2: 524395 | JN2: 365202 | JO2: 6272014 | JP2: 5028754 | JQ2: 104876 | JR2: 2439940 | JS2: 129430 | JT2: 89454 | JU2: 270459 | JV2: 562843 | JW2: 2520987 | JX2: 522676 | JY2: 245480 | JZ2: 1684071 | KA2: 717986 | KB2: 169356 | KC2: 201064 | KD2: 197532 | KE2: 1487302 | KF2: 152950 | KG2: 433015 | KH2: 181436 | KI2: 563020 | KJ2: 1341248 | KK2: 4675704 | KL2: 314986 | KM2: 228522 | KN2: 1058413 | KO2: 336522 | KP2: 144952 | KQ2: 99693 | KR2: 2426388 | KS2: 188665 | KT2: 202458 | KU2: 196431 | KV2: 120012 | KW2: 2810850 | KX2: 438906 | KY2: 437613 | KZ2: 129736 | LA2: 1275870 | LB2: 120986 | LC2: 2662733 | LD2: 3288774 | LE2: 114575 | LF2: 4645029 | LG2: 1969337 | LH2: 2052186 | LI2: 281555 | LJ2: 264926 | LK2: 156105 | LL2: 443701 | LM2: 485040 | LN2: 418285 | LO2: 569788 | LP2: 4061920 | LQ2: 166936 | LR2: 105702 | LS2: 117991 | LT2: 143337 | LU2: 386819 | LV2: 125566 | LW2: 144682 | LX2: 298181 | LY2: 272421 | LZ2: 324560 | MA2: 374737 | MB2: 597123 | MC2: 207042 | MD2: 462815 | ME2: 486785 | MF2: 135158 | MG2: 158576 | MH2: 126822 | MI2: 797334 | MJ2: 104725 | MK2: 656410 | ML2: 391730 | MM2: 3304691 | MN2: 168719 | MO2: 146296 | MP2: 602322 | MQ2: 232468 | MR2: 155449 | MS2: 385864 | MT2: 1060490 | MU2: 1037534 | MV2: 278526 | MW2: 118907 | MX2: 241740 | MY2: 1001146 | MZ2: 288881 | NA2: 150188 | NB2: 451918 | NC2: 98554 | ND2: 153305 | NE2: 1787235 | NF2: 478693 | NG2: 302045 | NH2: 62161 | NI2: 198209 | NJ2: 6318377 | NK2: 454969 | NL2: 168637 | NM2: 115040 | NN2: 138403 | NO2: 114754 | NP2: 124538 | NQ2: 136920 | NR2: 652622 | NS2: 149358 | NT2: 143408 | NU2: 113489 | NV2: 453347 | NW2: 146386 | NX2: 689766 | NY2: 867788 | NZ2: 257152 | OA2: 462924 | OB2: 427420 | OC2: 183364 | OD2: 211741
A3: Male: | B3: 91928 | C3: 121763 | D3: 341672 | E3: 68992 | F3: 65202 | G3: 446223 | H3: 454609 | I3: 74183 | J3: 432307 | K3: 59834 | L3: 136515 | M3: 66260 | N3: 75413 | O3: 206814 | P3: 184472 | Q3: 56174 | R3: 123857 | S3: 85915 | T3: 200585 | U3: 106519 | V3: 3036071 | W3: 180426 | X3: 98089 | Y3: 304383 | Z3: 1226850 | AA3: 465565 | AB3: 1376674 | AC3: 76849 | AD3: 111539 | AE3: 429375 | AF3: 66004 | AG3: 51098 | AH3: 201348 | AI3: 56800 | AJ3: 114239 | AK3: 128711 | AL3: 94065 | AM3: 121542 | AN3: 571470 | AO3: 68633 | AP3: 91355 | AQ3: 83855 | AR3: 81314 | AS3: 407870 | AT3: 2422844 | AU3: 165850 | AV3: 92772 | AW3: 64951 | AX3: 142590 | AY3: 469672 | AZ3: 210378 | BA3: 55017 | BB3: 566263 | BC3: 84742 | BD3: 112320 | BE3: 196306 | BF3: 402006 | BG3: 48202 | BH3: 30377 | BI3: 40441 | BJ3: 137510 | BK3: 77811 | BL3: 118854 | BM3: 100276 | BN3: 408201 | BO3: 1351259 | BP3: 107855 | BQ3: 280915 | BR3: 51357 | BS3: 4613694 | BT3: 103536 | BU3: 1121000 | BV3: 168283 | BW3: 1058278 | BX3: 63138 | BY3: 90899 | BZ3: 139879 | CA3: 390315 | CB3: 104673 | CC3: 411321 | CD3: 159736 | CE3: 42297 | CF3: 1078242 | CG3: 223223 | CH3: 48531 | CI3: 151773 | CJ3: 3954206 | CK3: 72055 | CL3: 120360 | CM3: 188896 | CN3: 398724 | CO3: 78295 | CP3: 49036 | CQ3: 344959 | CR3: 1513294 | CS3: 364958 | CT3: 2145311 | CU3: 73689 | CV3: 90210 | CW3: 49148 | CX3: 142558 | CY3: 288699 | CZ3: 29073 | DA3: 87781 | DB3: 92641 | DC3: 62959 | DD3: 102892 | DE3: 40844 | DF3: 435242 | DG3: 31128 | DH3: 133693 | DI3: 189618 | DJ3: 132776 | DK3: 52108 | DL3: 130898 | DM3: 59628 | DN3: 194403 | DO3: 290060 | DP3: 71308 | DQ3: 195402 | DR3: 94186 | DS3: 74147 | DT3: 51843 | DU3: 183519 | DV3: 113308 | DW3: 224529 | DX3: 588769 | DY3: 50075 | DZ3: 169664 | EA3: 106430 | EB3: 52832 | EC3: 63668 | ED3: 59094 | EE3: 53374 | EF3: 39262 | EG3: 78451 | EH3: 582691 | EI3: 43030 | EJ3: 43121 | EK3: 177898 | EL3: 166326 | EM3: 377782 | EN3: 83197 | EO3: 469120 | EP3: 32074 | EQ3: 206624 | ER3: 152858 | ES3: 66771 | ET3: 84750 | EU3: 298627 | EV3: 67354 | EW3: 565606 | EX3: 73967 | EY3: 46733 | EZ3: 183017 | FA3: 112883 | FB3: 43453 | FC3: 79798 | FD3: 48267 | FE3: 100217 | FF3: 3697808 | FG3: 182466 | FH3: 255573 | FI3: 83286 | FJ3: 1046919 | FK3: 89099 | FL3: 50893 | FM3: 82097 | FN3: 293506 | FO3: 87267 | FP3: 822744 | FQ3: 114477 | FR3: 81804 | FS3: 76643 | FT3: 103494 | FU3: 65599 | FV3: 66152 | FW3: 100213 | FX3: 81991 | FY3: 128637 | FZ3: 52797 | GA3: 1096131 | GB3: 158285 | GC3: 83494 | GD3: 246621 | GE3: 153389 | GF3: 90817 | GG3: 351185 | GH3: 459458 | GI3: 40525 | GJ3: 84407 | GK3: 201830 | GL3: 116253 | GM3: 119751 | GN3: 111453 | GO3: 389873 | GP3: 274372 | GQ3: 232167 | GR3: 133726 | GS3: 110735 | GT3: 1165712 | GU3: 59656 | GV3: 65841 | GW3: 71185 | GX3: 32320 | GY3: 55895 | GZ3: 257124 | HA3: 105079 | HB3: 50605 | HC3: 173391 | HD3: 367547 | HE3: 78131 | HF3: 144582 | HG3: 56077 | HH3: 6426049 | HI3: 674888 | HJ3: 178045 | HK3: 127396 | HL3: 112820 | HM3: 347291 | HN3: 213975 | HO3: 70216 | HP3: 52728 | HQ3: 64040 | HR3: 99646 | HS3: 440466 | HT3: 109169 | HU3: 641979 | HV3: 147232 | HW3: 3062310 | HX3: 58096 | HY3: 41776 | HZ3: 92062 | IA3: 769287 | IB3: 1851989 | IC3: 39782 | ID3: 63159 | IE3: 197311 | IF3: 276407 | IG3: 108248 | IH3: 77504 | II3: 184023 | IJ3: 73592 | IK3: 60229 | IL3: 65387 | IM3: 54278 | IN3: 87788 | IO3: 185457 | IP3: 67434 | IQ3: 196300 | IR3: 1022167 | IS3: 275802 | IT3: 472931 | IU3: 9647694 | IV3: 75376 | IW3: 428920 | IX3: 140096 | IY3: 193338 | IZ3: 84466 | JA3: 331220 | JB3: 723471 | JC3: 146977 | JD3: 489981 | JE3: 1371906 | JF3: 87239 | JG3: 55315 | JH3: 416606 | JI3: 50367 | JJ3: 311716 | JK3: 106100 | JL3: 43408 | JM3: 262307 | JN3: 179904 | JO3: 3046206 | JP3: 2510733 | JQ3: 51351 | JR3: 1199000 | JS3: 63381 | JT3: 44850 | JU3: 128612 | JV3: 275553 | JW3: 1255791 | JX3: 257453 | JY3: 120844 | JZ3: 825294 | KA3: 364551 | KB3: 84054 | KC3: 98902 | KD3: 98405 | KE3: 729358 | KF3: 78284 | KG3: 214748 | KH3: 89288 | KI3: 286904 | KJ3: 651491 | KK3: 2342638 | KL3: 151863 | KM3: 112663 | KN3: 517728 | KO3: 165410 | KP3: 69276 | KQ3: 48820 | KR3: 1194559 | KS3: 92054 | KT3: 102408 | KU3: 97874 | KV3: 61062 | KW3: 1371757 | KX3: 219536 | KY3: 223242 | KZ3: 64134 | LA3: 645743 | LB3: 60480 | LC3: 1323954 | LD3: 1662238 | LE3: 56710 | LF3: 2314748 | LG3: 1003293 | LH3: 962432 | LI3: 141966 | LJ3: 132027 | LK3: 76208 | LL3: 222371 | LM3: 238643 | LN3: 202819 | LO3: 282767 | LP3: 2052180 | LQ3: 80832 | LR3: 51698 | LS3: 59992 | LT3: 70117 | LU3: 186329 | LV3: 63772 | LW3: 73040 | LX3: 150871 | LY3: 133315 | LZ3: 159295 | MA3: 182445 | MB3: 298250 | MC3: 100036 | MD3: 225126 | ME3: 239162 | MF3: 66310 | MG3: 83539 | MH3: 62926 | MI3: 399104 | MJ3: 50561 | MK3: 321414 | ML3: 189015 | MM3: 1615614 | MN3: 85823 | MO3: 72964 | MP3: 294452 | MQ3: 114348 | MR3: 77438 | MS3: 190728 | MT3: 524257 | MU3: 512706 | MV3: 134700 | MW3: 59428 | MX3: 117074 | MY3: 505293 | MZ3: 144481 | NA3: 72185 | NB3: 225472 | NC3: 48602 | ND3: 78123 | NE3: 877211 | NF3: 239638 | NG3: 147860 | NH3: 31546 | NI3: 96254 | NJ3: 3107522 | NK3: 222483 | NL3: 83085 | NM3: 60361 | NN3: 69850 | NO3: 56450 | NP3: 63418 | NQ3: 69363 | NR3: 324999 | NS3: 77088 | NT3: 71000 | NU3: 56006 | NV3: 218532 | NW3: 73606 | NX3: 333335 | NY3: 431017 | NZ3: 128913 | OA3: 230316 | OB3: 210044 | OC3: 92245 | OD3: 109174
A4: Under 5 years | B4: 5805 | C4: 3845 | D4: 18026 | E4: 4553 | F4: 3662 | G4: 22469 | H4: 23029 | I4: 4814 | J4: 22726 | K4: 3083 | L4: 8498 | M4: 2944 | N4: 2467 | O4: 12938 | P4: 8673 | Q4: 3472 | R4: 6976 | S4: 2696 | T4: 9477 | U4: 5533 | V4: 185569 | W4: 9094 | X4: 5375 | Y4: 18846 | Z4: 71601 | AA4: 32913 | AB4: 82965 | AC4: 3322 | AD4: 4080 | AE4: 27266 | AF4: 3968 | AG4: 2468 | AH4: 12891 | AI4: 2781 | AJ4: 5297 | AK4: 6003 | AL4: 5202 | AM4: 5994 | AN4: 35116 | AO4: 3768 | AP4: 3574 | AQ4: 4499 | AR4: 3550 | AS4: 23235 | AT4: 127203 | AU4: 6431 | AV4: 5970 | AW4: 2850 | AX4: 7533 | AY4: 26149 | AZ4: 15370 | BA4: 2907 | BB4: 30619 | BC4: 5107 | BD4: 5319 | BE4: 11035 | BF4: 18652 | BG4: 2913 | BH4: 1379 | BI4: 2274 | BJ4: 8028 | BK4: 4416 | BL4: 6304 | BM4: 5126 | BN4: 24779 | BO4: 84123 | BP4: 5836 | BQ4: 16471 | BR4: 2781 | BS4: 260700 | BT4: 5550 | BU4: 68650 | BV4: 13719 | BW4: 58438 | BX4: 3596 | BY4: 5160 | BZ4: 7689 | CA4: 23932 | CB4: 5837 | CC4: 24202 | CD4: 10491 | CE4: 2710 | CF4: 68823 | CG4: 13861 | CH4: 1860 | CI4: 9237 | CJ4: 260307 | CK4: 4450 | CL4: 6492 | CM4: 10843 | CN4: 23720 | CO4: 4942 | CP4: 3171 | CQ4: 15352 | CR4: 83630 | CS4: 23838 | CT4: 124692 | CU4: 4471 | CV4: 5607 | CW4: 3022 | CX4: 6708 | CY4: 15758 | CZ4: 2616 | DA4: 4577 | DB4: 6443 | DC4: 3911 | DD4: 7734 | DE4: 2137 | DF4: 29448 | DG4: 1934 | DH4: 7072 | DI4: 8357 | DJ4: 7754 | DK4: 3527 | DL4: 8290 | DM4: 3436 | DN4: 14751 | DO4: 19206 | DP4: 3430 | DQ4: 11452 | DR4: 5971 | DS4: 4309 | DT4: 2763 | DU4: 8149 | DV4: 7169 | DW4: 15430 | DX4: 41656 | DY4: 3030 | DZ4: 8411 | EA4: 6562 | EB4: 2521 | EC4: 2847 | ED4: 3858 | EE4: 3334 | EF4: 2976 | EG4: 3901 | EH4: 34689 | EI4: 2038 | EJ4: 2460 | EK4: 12141 | EL4: 9454 | EM4: 22009 | EN4: 4902 | EO4: 28041 | EP4: 1178 | EQ4: 12719 | ER4: 8585 | ES4: 4898 | ET4: 5505 | EU4: 17209 | EV4: 4092 | EW4: 29230 | EX4: 4771 | EY4: 2447 | EZ4: 9849 | FA4: 5416 | FB4: 3902 | FC4: 3006 | FD4: 2556 | FE4: 6373 | FF4: 250813 | FG4: 9778 | FH4: 14880 | FI4: 5984 | FJ4: 68650 | FK4: 5174 | FL4: 1928 | FM4: 4303 | FN4: 18948 | FO4: 5333 | FP4: 48990 | FQ4: 8542 | FR4: 4841 | FS4: 4435 | FT4: 4836 | FU4: 3191 | FV4: 4556 | FW4: 6418 | FX4: 4582 | FY4: 7274 | FZ4: 3089 | GA4: 68334 | GB4: 10901 | GC4: 4458 | GD4: 18688 | GE4: 7265 | GF4: 4075 | GG4: 20766 | GH4: 24875 | GI4: 2510 | GJ4: 4412 | GK4: 13750 | GL4: 6251 | GM4: 8190 | GN4: 4538 | GO4: 22700 | GP4: 17876 | GQ4: 12371 | GR4: 11062 | GS4: 6726 | GT4: 66860 | GU4: 2684 | GV4: 4234 | GW4: 4134 | GX4: 1770 | GY4: 3043 | GZ4: 15468 | HA4: 6210 | HB4: 3107 | HC4: 10205 | HD4: 23124 | HE4: 6015 | HF4: 8993 | HG4: 3278 | HH4: 340660 | HI4: 41254 | HJ4: 11444 | HK4: 6418 | HL4: 7258 | HM4: 17978 | HN4: 10888 | HO4: 4792 | HP4: 2660 | HQ4: 3544 | HR4: 3170 | HS4: 35616 | HT4: 5586 | HU4: 44209 | HV4: 10545 | HW4: 168822 | HX4: 3106 | HY4: 2289 | HZ4: 7712 | IA4: 46372 | IB4: 112823 | IC4: 2632 | ID4: 3074 | IE4: 13436 | IF4: 18670 | IG4: 6960 | IH4: 4050 | II4: 12346 | IJ4: 3294 | IK4: 3255 | IL4: 3566 | IM4: 2764 | IN4: 5113 | IO4: 8275 | IP4: 3049 | IQ4: 8255 | IR4: 65158 | IS4: 14503 | IT4: 29478 | IU4: 573248 | IV4: 4121 | IW4: 17245 | IX4: 6861 | IY4: 9744 | IZ4: 7289 | JA4: 22831 | JB4: 45735 | JC4: 8185 | JD4: 32664 | JE4: 77448 | JF4: 4586 | JG4: 3581 | JH4: 22417 | JI4: 2914 | JJ4: 14086 | JK4: 5863 | JL4: 2358 | JM4: 14583 | JN4: 11044 | JO4: 175431 | JP4: 143528 | JQ4: 3102 | JR4: 60557 | JS4: 2594 | JT4: 2768 | JU4: 4667 | JV4: 13100 | JW4: 65116 | JX4: 12139 | JY4: 4616 | JZ4: 42135 | KA4: 31041 | KB4: 4558 | KC4: 2869 | KD4: 5817 | KE4: 43883 | KF4: 4456 | KG4: 12122 | KH4: 4791 | KI4: 15206 | KJ4: 38550 | KK4: 145131 | KL4: 7803 | KM4: 7148 | KN4: 27240 | KO4: 10194 | KP4: 4153 | KQ4: 3000 | KR4: 69101 | KS4: 5281 | KT4: 6543 | KU4: 5870 | KV4: 3496 | KW4: 79579 | KX4: 12779 | KY4: 14373 | KZ4: 4060 | LA4: 42023 | LB4: 3862 | LC4: 84528 | LD4: 93974 | LE4: 2530 | LF4: 118706 | LG4: 53117 | LH4: 33288 | LI4: 6202 | LJ4: 5840 | LK4: 2904 | LL4: 13760 | LM4: 11480 | LN4: 12863 | LO4: 15025 | LP4: 115944 | LQ4: 3283 | LR4: 2086 | LS4: 3202 | LT4: 4433 | LU4: 12144 | LV4: 3195 | LW4: 4932 | LX4: 10360 | LY4: 7934 | LZ4: 9693 | MA4: 11421 | MB4: 16817 | MC4: 5857 | MD4: 12408 | ME4: 14513 | MF4: 3989 | MG4: 2908 | MH4: 3295 | MI4: 26263 | MJ4: 3571 | MK4: 17463 | ML4: 10231 | MM4: 83232 | MN4: 4633 | MO4: 4250 | MP4: 17540 | MQ4: 6795 | MR4: 3699 | MS4: 11119 | MT4: 26598 | MU4: 33207 | MV4: 7864 | MW4: 3912 | MX4: 7732 | MY4: 29195 | MZ4: 7953 | NA4: 4983 | NB4: 13190 | NC4: 3306 | ND4: 4834 | NE4: 54341 | NF4: 17659 | NG4: 9507 | NH4: 1508 | NI4: 6091 | NJ4: 192077 | NK4: 11854 | NL4: 5072 | NM4: 4269 | NN4: 3806 | NO4: 2772 | NP4: 3723 | NQ4: 3366 | NR4: 20654 | NS4: 4547 | NT4: 1122 | NU4: 2990 | NV4: 10356 | NW4: 3921 | NX4: 19344 | NY4: 23089 | NZ4: 9295 | OA4: 12934 | OB4: 11770 | OC4: 6353 | OD4: 7143
A5: 5 to 9 years | B5: 6278 | C5: 5333 | D5: 20721 | E5: 4534 | F5: 4204 | G5: 26263 | H5: 26240 | I5: 5057 | J5: 25089 | K5: 3270 | L5: 9662 | M5: 3192 | N5: 3205 | O5: 14228 | P5: 9195 | Q5: 3442 | R5: 8143 | S5: 3833 | T5: 11474 | U5: 6596 | V5: 202535 | W5: 10054 | X5: 5375 | Y5: 19768 | Z5: 73158 | AA5: 36390 | AB5: 86911 | AC5: 4012 | AD5: 4632 | AE5: 30286 | AF5: 4477 | AG5: 3112 | AH5: 14086 | AI5: 3167 | AJ5: 6615 | AK5: 6959 | AL5: 6259 | AM5: 6089 | AN5: 37525 | AO5: 4485 | AP5: 3792 | AQ5: 4626 | AR5: 3821 | AS5: 25872 | AT5: 134486 | AU5: 7985 | AV5: 5854 | AW5: 3008 | AX5: 7990 | AY5: 28432 | AZ5: 17970 | BA5: 2706 | BB5: 33547 | BC5: 5174 | BD5: 5657 | BE5: 11995 | BF5: 18498 | BG5: 2823 | BH5: 1548 | BI5: 2681 | BJ5: 7920 | BK5: 5560 | BL5: 6572 | BM5: 5243 | BN5: 25514 | BO5: 87779 | BP5: 6287 | BQ5: 16657 | BR5: 3333 | BS5: 291451 | BT5: 6495 | BU5: 75205 | BV5: 13610 | BW5: 63981 | BX5: 3861 | BY5: 6352 | BZ5: 8423 | CA5: 24287 | CB5: 6748 | CC5: 26155 | CD5: 12153 | CE5: 2710 | CF5: 71690 | CG5: 15825 | CH5: 1958 | CI5: 9586 | CJ5: 278758 | CK5: 4655 | CL5: 7226 | CM5: 12628 | CN5: 26165 | CO5: 5010 | CP5: 3352 | CQ5: 16855 | CR5: 85777 | CS5: 25612 | CT5: 132702 | CU5: 5294 | CV5: 6987 | CW5: 3599 | CX5: 7455 | CY5: 15096 | CZ5: 2089 | DA5: 4688 | DB5: 6339 | DC5: 4109 | DD5: 7635 | DE5: 2285 | DF5: 29778 | DG5: 2417 | DH5: 6918 | DI5: 9346 | DJ5: 8587 | DK5: 3391 | DL5: 8652 | DM5: 4164 | DN5: 14671 | DO5: 20457 | DP5: 4045 | DQ5: 12498 | DR5: 6276 | DS5: 4366 | DT5: 2641 | DU5: 9132 | DV5: 8500 | DW5: 15941 | DX5: 44849 | DY5: 3138 | DZ5: 8297 | EA5: 6660 | EB5: 2943 | EC5: 3271 | ED5: 4150 | EE5: 3383 | EF5: 2967 | EG5: 4457 | EH5: 38552 | EI5: 2073 | EJ5: 2858 | EK5: 11992 | EL5: 10328 | EM5: 25496 | EN5: 5157 | EO5: 30737 | EP5: 1213 | EQ5: 12693 | ER5: 9073 | ES5: 4385 | ET5: 5672 | EU5: 18007 | EV5: 3681 | EW5: 30311 | EX5: 4849 | EY5: 2724 | EZ5: 10217 | FA5: 5160 | FB5: 3134 | FC5: 4160 | FD5: 2903 | FE5: 6319 | FF5: 274657 | FG5: 11665 | FH5: 15446 | FI5: 7679 | FJ5: 73856 | FK5: 5792 | FL5: 2082 | FM5: 5025 | FN5: 18673 | FO5: 5161 | FP5: 52784 | FQ5: 7256 | FR5: 5751 | FS5: 4353 | FT5: 5573 | FU5: 3702 | FV5: 4611 | FW5: 7228 | FX5: 4401 | FY5: 7891 | FZ5: 3264 | GA5: 74452 | GB5: 11989 | GC5: 5209 | GD5: 19523 | GE5: 7612 | GF5: 4096 | GG5: 21313 | GH5: 26443 | GI5: 2772 | GJ5: 4562 | GK5: 13923 | GL5: 6015 | GM5: 8058 | GN5: 5252 | GO5: 23574 | GP5: 18071 | GQ5: 13500 | GR5: 12878 | GS5: 6582 | GT5: 71228 | GU5: 3441 | GV5: 4083 | GW5: 4430 | GX5: 1883 | GY5: 3247 | GZ5: 16862 | HA5: 7704 | HB5: 3471 | HC5: 10710 | HD5: 24772 | HE5: 7046 | HF5: 9427 | HG5: 3762 | HH5: 367253 | HI5: 42864 | HJ5: 12245 | HK5: 7740 | HL5: 7078 | HM5: 19589 | HN5: 11278 | HO5: 4105 | HP5: 2915 | HQ5: 3606 | HR5: 4170 | HS5: 37595 | HT5: 7093 | HU5: 47495 | HV5: 11693 | HW5: 170581 | HX5: 3507 | HY5: 2473 | HZ5: 8230 | IA5: 50285 | IB5: 122710 | IC5: 2750 | ID5: 2775 | IE5: 12719 | IF5: 20448 | IG5: 7599 | IH5: 4853 | II5: 12641 | IJ5: 3168 | IK5: 3790 | IL5: 3944 | IM5: 2920 | IN5: 5457 | IO5: 8580 | IP5: 3700 | IQ5: 8308 | IR5: 66579 | IS5: 14988 | IT5: 29624 | IU5: 574452 | IV5: 4955 | IW5: 18389 | IX5: 7262 | IY5: 9082 | IZ5: 7681 | JA5: 27719 | JB5: 50379 | JC5: 8596 | JD5: 34860 | JE5: 85453 | JF5: 5042 | JG5: 3921 | JH5: 24851 | JI5: 3522 | JJ5: 15897 | JK5: 5863 | JL5: 2810 | JM5: 16938 | JN5: 12552 | JO5: 184851 | JP5: 156347 | JQ5: 3073 | JR5: 65222 | JS5: 3039 | JT5: 3378 | JU5: 6329 | JV5: 14285 | JW5: 72664 | JX5: 13324 | JY5: 5039 | JZ5: 44710 | KA5: 31378 | KB5: 5018 | KC5: 3490 | KD5: 6843 | KE5: 48472 | KF5: 4776 | KG5: 13929 | KH5: 5491 | KI5: 16575 | KJ5: 40683 | KK5: 160115 | KL5: 8179 | KM5: 7637 | KN5: 29877 | KO5: 10732 | KP5: 4977 | KQ5: 3115 | KR5: 73919 | KS5: 5540 | KT5: 6891 | KU5: 6596 | KV5: 3895 | KW5: 86449 | KX5: 14356 | KY5: 15858 | KZ5: 4234 | LA5: 45580 | LB5: 4591 | LC5: 92593 | LD5: 95405 | LE5: 3030 | LF5: 122288 | LG5: 56332 | LH5: 44479 | LI5: 6500 | LJ5: 6761 | LK5: 3712 | LL5: 13800 | LM5: 13048 | LN5: 13954 | LO5: 15794 | LP5: 122214 | LQ5: 3606 | LR5: 2466 | LS5: 3353 | LT5: 4873 | LU5: 12040 | LV5: 4055 | LW5: 5001 | LX5: 10675 | LY5: 9723 | LZ5: 10566 | MA5: 12620 | MB5: 18887 | MC5: 6355 | MD5: 12496 | ME5: 16115 | MF5: 4593 | MG5: 3437 | MH5: 3761 | MI5: 28725 | MJ5: 3461 | MK5: 18812 | ML5: 10354 | MM5: 87568 | MN5: 4905 | MO5: 4520 | MP5: 19631 | MQ5: 7530 | MR5: 3649 | MS5: 11954 | MT5: 30295 | MU5: 34904 | MV5: 8748 | MW5: 4370 | MX5: 9001 | MY5: 29982 | MZ5: 8764 | NA5: 4413 | NB5: 13894 | NC5: 3175 | ND5: 5407 | NE5: 55858 | NF5: 19840 | NG5: 10366 | NH5: 1824 | NI5: 7446 | NJ5: 203096 | NK5: 12597 | NL5: 5279 | NM5: 4155 | NN5: 4036 | NO5: 3243 | NP5: 4080 | NQ5: 3897 | NR5: 21645 | NS5: 4807 | NT5: 1512 | NU5: 3728 | NV5: 10364 | NW5: 4783 | NX5: 20200 | NY5: 24398 | NZ5: 10535 | OA5: 14163 | OB5: 12050 | OC5: 7345 | OD5: 7640
A6: 10 to 14 years | B6: 5839 | C6: 6601 | D6: 19913 | E6: 5553 | F6: 4109 | G6: 24133 | H6: 30002 | I6: 5528 | J6: 26988 | K6: 3897 | L6: 10186 | M6: 3038 | N6: 3586 | O6: 14081 | P6: 10175 | Q6: 3598 | R6: 8423 | S6: 4658 | T6: 10045 | U6: 6321 | V6: 221291 | W6: 11465 | X6: 6368 | Y6: 21137 | Z6: 79205 | AA6: 40352 | AB6: 94075 | AC6: 4016 | AD6: 4609 | AE6: 28391 | AF6: 4438 | AG6: 2826 | AH6: 14789 | AI6: 3973 | AJ6: 6185 | AK6: 7873 | AL6: 6328 | AM6: 7857 | AN6: 40814 | AO6: 5061 | AP6: 4483 | AQ6: 5879 | AR6: 4005 | AS6: 29919 | AT6: 138278 | AU6: 8936 | AV6: 6382 | AW6: 4029 | AX6: 7792 | AY6: 31319 | AZ6: 17698 | BA6: 4180 | BB6: 33909 | BC6: 6145 | BD6: 6090 | BE6: 12897 | BF6: 21618 | BG6: 3320 | BH6: 1933 | BI6: 2986 | BJ6: 9864 | BK6: 4474 | BL6: 6706 | BM6: 6747 | BN6: 26045 | BO6: 96366 | BP6: 5967 | BQ6: 18139 | BR6: 3353 | BS6: 304545 | BT6: 6000 | BU6: 76097 | BV6: 11484 | BW6: 65913 | BX6: 3970 | BY6: 5696 | BZ6: 7879 | CA6: 26280 | CB6: 5925 | CC6: 27741 | CD6: 10491 | CE6: 3193 | CF6: 74424 | CG6: 14906 | CH6: 2463 | CI6: 9303 | CJ6: 298968 | CK6: 5413 | CL6: 8054 | CM6: 12393 | CN6: 25653 | CO6: 5693 | CP6: 3292 | CQ6: 18296 | CR6: 95065 | CS6: 26360 | CT6: 140516 | CU6: 4634 | CV6: 5507 | CW6: 2737 | CX6: 8242 | CY6: 18420 | CZ6: 3144 | DA6: 5590 | DB6: 8684 | DC6: 4959 | DD6: 8441 | DE6: 2748 | DF6: 36102 | DG6: 2323 | DH6: 9236 | DI6: 10536 | DJ6: 8718 | DK6: 3386 | DL6: 8577 | DM6: 4609 | DN6: 13383 | DO6: 20370 | DP6: 4106 | DQ6: 13464 | DR6: 7054 | DS6: 4533 | DT6: 3638 | DU6: 10585 | DV6: 7207 | DW6: 17125 | DX6: 50942 | DY6: 3405 | DZ6: 10226 | EA6: 7807 | EB6: 3245 | EC6: 3466 | ED6: 3849 | EE6: 3326 | EF6: 2941 | EG6: 4869 | EH6: 39078 | EI6: 2941 | EJ6: 2894 | EK6: 13748 | EL6: 11277 | EM6: 24109 | EN6: 5639 | EO6: 30955 | EP6: 2068 | EQ6: 15214 | ER6: 10110 | ES6: 5040 | ET6: 6184 | EU6: 19628 | EV6: 4253 | EW6: 34178 | EX6: 5617 | EY6: 2884 | EZ6: 11243 | FA6: 6312 | FB6: 3449 | FC6: 3352 | FD6: 2809 | FE6: 7696 | FF6: 283814 | FG6: 11022 | FH6: 16582 | FI6: 7032 | FJ6: 77618 | FK6: 4471 | FL6: 2128 | FM6: 4757 | FN6: 22329 | FO6: 6722 | FP6: 55620 | FQ6: 6871 | FR6: 4966 | FS6: 5061 | FT6: 5573 | FU6: 3675 | FV6: 5306 | FW6: 6958 | FX6: 6000 | FY6: 8420 | FZ6: 3691 | GA6: 77836 | GB6: 13267 | GC6: 5559 | GD6: 17618 | GE6: 9284 | GF6: 4717 | GG6: 23958 | GH6: 28497 | GI6: 2759 | GJ6: 5644 | GK6: 14833 | GL6: 7440 | GM6: 9436 | GN6: 4979 | GO6: 26989 | GP6: 18885 | GQ6: 13840 | GR6: 11603 | GS6: 8411 | GT6: 79375 | GU6: 2767 | GV6: 4598 | GW6: 5093 | GX6: 1951 | GY6: 3586 | GZ6: 16153 | HA6: 6788 | HB6: 3477 | HC6: 11794 | HD6: 26318 | HE6: 6101 | HF6: 11192 | HG6: 3692 | HH6: 416259 | HI6: 45747 | HJ6: 12195 | HK6: 7347 | HL6: 8851 | HM6: 20863 | HN6: 12729 | HO6: 4451 | HP6: 3379 | HQ6: 4183 | HR6: 5595 | HS6: 43415 | HT6: 6454 | HU6: 48808 | HV6: 12912 | HW6: 183995 | HX6: 3450 | HY6: 2853 | HZ6: 7062 | IA6: 51783 | IB6: 126723 | IC6: 2486 | ID6: 3804 | IE6: 14274 | IF6: 22476 | IG6: 7906 | IH6: 4708 | II6: 12986 | IJ6: 3585 | IK6: 4036 | IL6: 4071 | IM6: 2900 | IN6: 6017 | IO6: 10078 | IP6: 3910 | IQ6: 10200 | IR6: 68996 | IS6: 16850 | IT6: 31812 | IU6: 623285 | IV6: 4514 | IW6: 21973 | IX6: 8436 | IY6: 12880 | IZ6: 6535 | JA6: 28307 | JB6: 52512 | JC6: 9934 | JD6: 36800 | JE6: 86534 | JF6: 5016 | JG6: 4072 | JH6: 28229 | JI6: 3139 | JJ6: 17620 | JK6: 7073 | JL6: 2507 | JM6: 15397 | JN6: 12057 | JO6: 199877 | JP6: 169314 | JQ6: 3634 | JR6: 67055 | JS6: 2846 | JT6: 3277 | JU6: 7843 | JV6: 15148 | JW6: 77201 | JX6: 14427 | JY6: 5912 | JZ6: 49441 | KA6: 34208 | KB6: 5789 | KC6: 3444 | KD6: 6245 | KE6: 51491 | KF6: 4473 | KG6: 13738 | KH6: 6169 | KI6: 17135 | KJ6: 41831 | KK6: 178034 | KL6: 10040 | KM6: 8137 | KN6: 31781 | KO6: 12320 | KP6: 4303 | KQ6: 3363 | KR6: 82940 | KS6: 6234 | KT6: 7089 | KU6: 7599 | KV6: 3877 | KW6: 91407 | KX6: 15280 | KY6: 16768 | KZ6: 3948 | LA6: 48998 | LB6: 3792 | LC6: 95201 | LD6: 103193 | LE6: 3309 | LF6: 133317 | LG6: 61020 | LH6: 53216 | LI6: 7768 | LJ6: 7509 | LK6: 3527 | LL6: 14472 | LM6: 13645 | LN6: 13173 | LO6: 17511 | LP6: 122453 | LQ6: 3551 | LR6: 2629 | LS6: 4000 | LT6: 5068 | LU6: 14825 | LV6: 3447 | LW6: 5923 | LX6: 11623 | LY6: 8837 | LZ6: 10703 | MA6: 12203 | MB6: 18631 | MC6: 6812 | MD6: 15510 | ME6: 15619 | MF6: 4263 | MG6: 3236 | MH6: 3275 | MI6: 32757 | MJ6: 3556 | MK6: 20533 | ML6: 11152 | MM6: 98198 | MN6: 5341 | MO6: 5757 | MP6: 19034 | MQ6: 8123 | MR6: 4755 | MS6: 12818 | MT6: 30017 | MU6: 38823 | MV6: 7924 | MW6: 5164 | MX6: 7950 | MY6: 30289 | MZ6: 9180 | NA6: 5928 | NB6: 14769 | NC6: 3817 | ND6: 5384 | NE6: 57380 | NF6: 22070 | NG6: 10126 | NH6: 1959 | NI6: 7044 | NJ6: 211834 | NK6: 13814 | NL6: 5295 | NM6: 3629 | NN6: 4981 | NO6: 3184 | NP6: 4666 | NQ6: 3664 | NR6: 25335 | NS6: 5049 | NT6: 1395 | NU6: 2985 | NV6: 12340 | NW6: 4661 | NX6: 23521 | NY6: 27295 | NZ6: 11383 | OA6: 15488 | OB6: 12817 | OC6: 6518 | OD6: 7189
