Workbook

Sheet KPI Summary
A1: Last Season Player Role Baselines
B2: AVERAGE | H2: MAX | K2: STANDARD DEVIATION
A3: Position | B3: PL | C3: High IMA | D3: MII 1 | E3: MII 2 | F3: MII 3 | G3: PL 3+ | H3: MII 1 | I3: MII 2 | J3: MII 3 | K3: PL | L3: High IMA | M3: MII 1 | N3: MII 2 | O3: MII 3 | P3: PL 3+
A4: Point Guard | B4: ='PL numbers'!C21 -> 619.54839 | C4: ='High IMA numbers'!C21 -> 72.419355 | D4: ='MII 1 numbers'!C21 -> 21.451613 | E4: ='MII 2 numbers'!C21 -> 47.516129 | F4: ='MII 3 numbers'!C21 -> 71.258065 | G4: ='PL 3+ numbers'!C21 -> 173.74194 | H4: ='MII 1 numbers'!D21 -> 25 | I4: ='MII 2 numbers'!D21 -> 55 | J4: ='MII 3 numbers'!D21 -> 86 | K4: ='PL numbers'!E21 -> 157.03351 | L4: ='High IMA numbers'!E21 -> 20.774623 | M4: ='MII 1 numbers'!F21 -> 1.6296975 | N4: ='MII 2 numbers'!F21 -> 3.6043582 | O4: ='MII 3 numbers'!F21 -> 5.7327582 | P4: ='PL 3+ numbers'!E21 -> 5.7327582
A5: Primary Guard | B5: ='PL numbers'!C22 -> 546.97739 | C5: ='High IMA numbers'!C22 -> 47.896552 | D5: ='MII 1 numbers'!C22 -> 18.556705 | E5: ='MII 2 numbers'!C22 -> 41.680077 | F5: ='MII 3 numbers'!C22 -> 61.569732 | G5: ='PL 3+ numbers'!C22 -> 79.742146 | H5: ='MII 1 numbers'!D22 -> 22.333333 | I5: ='MII 2 numbers'!D22 -> 51 | J5: ='MII 3 numbers'!D22 -> 76.666667 | K5: ='PL numbers'!E22 -> 128.09404 | L5: ='High IMA numbers'!E22 -> 14.645208 | M5: ='MII 1 numbers'!F22 -> 2.0864799 | N5: ='MII 2 numbers'!F22 -> 4.5414753 | O5: ='MII 3 numbers'!F22 -> 7.0312998 | P5: ='PL 3+ numbers'!E22 -> 7.0312998
A6: Primary Forward | B6: ='PL numbers'!C23 -> 386.96667 | C6: ='High IMA numbers'!C23 -> 48.866667 | D6: ='MII 1 numbers'!C23 -> 18.566667 | E6: ='MII 2 numbers'!C23 -> 41.033333 | F6: ='MII 3 numbers'!C23 -> 57.433333 | G6: ='PL 3+ numbers'!C23 -> 65.233333 | H6: ='MII 1 numbers'!D23 -> 22 | I6: ='MII 2 numbers'!D23 -> 49 | J6: ='MII 3 numbers'!D23 -> 70 | K6: ='PL numbers'!E23 -> 81.823256 | L6: ='High IMA numbers'!E23 -> 12.538457 | M6: ='MII 1 numbers'!F23 -> 1.4345956 | N6: ='MII 2 numbers'!F23 -> 4.0118105 | O6: ='MII 3 numbers'!F23 -> 6.1492197 | P6: ='PL 3+ numbers'!E23 -> 6.1492197
A7: Secondary Guard | B7: ='PL numbers'!C24 -> 262.55518 | C7: ='High IMA numbers'!C24 -> 26.847826 | D7: ='MII 1 numbers'!C24 -> 17.170569 | E7: ='MII 2 numbers'!C24 -> 36.392977 | F7: ='MII 3 numbers'!C24 -> 47.012542 | G7: ='PL 3+ numbers'!C24 -> 41.445652 | H7: ='MII 1 numbers'!D24 -> 21 | I7: ='MII 2 numbers'!D24 -> 44 | J7: ='MII 3 numbers'!D24 -> 67.5 | K7: ='PL numbers'!E24 -> 121.39124 | L7: ='High IMA numbers'!E24 -> 12.011456 | M7: ='MII 1 numbers'!F24 -> 1.6499428 | N7: ='MII 2 numbers'!F24 -> 3.3913918 | O7: ='MII 3 numbers'!F24 -> 9.4889409 | P7: ='PL 3+ numbers'!E24 -> 9.4889409
A8: Secondary Forward | B8: ='PL numbers'!C25 -> 162.3871 | C8: ='High IMA numbers'!C25 -> 23.870968 | D8: ='MII 1 numbers'!C25 -> 17.870968 | E8: ='MII 2 numbers'!C25 -> 34.354839 | F8: ='MII 3 numbers'!C25 -> 38.774194 | G8: ='PL 3+ numbers'!C25 -> 26.483871 | H8: ='MII 1 numbers'!D25 -> 23 | I8: ='MII 2 numbers'!D25 -> 46 | J8: ='MII 3 numbers'!D25 -> 64 | K8: ='PL numbers'!E25 -> 89.726131 | L8: ='High IMA numbers'!E25 -> 14.65092 | M8: ='MII 1 numbers'!F25 -> 1.9956943 | N8: ='MII 2 numbers'!F25 -> 8.2952001 | O8: ='MII 3 numbers'!F25 -> 14.191899 | P8: ='PL 3+ numbers'!E25 -> 14.191899
A9: PRIMARY/STARTERS | B9: =AVERAGE(B4:B6) -> 517.83082 | C9: =AVERAGE(C4:C6) -> 56.394191 | D9: =AVERAGE(D4:D6) -> 19.524995 | E9: =AVERAGE(E4:E6) -> 43.409846 | F9: =AVERAGE(F4:F6) -> 63.420377 | G9: =AVERAGE(G4:G6) -> 106.23914 | H9: =AVERAGE(H4:H6) -> 23.111111 | I9: =AVERAGE(I4:I6) -> 51.666667 | ... P9: =AVERAGE(P4:P6) -> 6.3044259

Sheet Cheung_Morgan_Work_Sample
A1: wo | B1: redacted 1 | C1: redacted 2 | D1: redacted 3 | E1: redacted 4 | F1: redacted 5 | G1: redacted 6 | H1: redacted 7 | I1: redacted 8 | J1: redacted 9 | K1: redacted 10 | L1: redacted 11 | M1: redacted 12 | N1: redacted 13
A2: quarter | B2: time in | C2: time in | D2: time in | E2: time in | F2: time in | G2: time in | H2: time in | I2: time in | J2: time in | K2: time in | L2: time in | M2: time in | N2: time in
A3: 1 | B3: 0.32152778 | C3: 0.32152778 | D3: 0.19166667 | F3: 0.029861111 | G3: 0.32152778 | I3: 0.35277778 | L3: 0.32152778 | M3: 0.29166667
B4: 0.23680556 | C4: 0.31736111 | F4: 0.26527778 | G4: 0.16111111 | L4: 0.11597222 | M4: 0.0875
B5: 0.035416667
A7: 2 | B7: 0.36041667 | C7: 0.21319444 | D7: 0.21319444 | F7: 0.28888889 | G7: 0.097916667 | I7: 0.21319444 | L7: 0.21319444 | M7: 0.21319444
C8: 0.36041667 | D8: 0.093055556 | I8: 0.16944444 | L8: 0.36041667 | M8: 0.071527778
A11: 3 | B11: 0.35 | C11: 0.35 | F11: 0.15902778 | G11: 0.31527778 | I11: 0.034027778 | L11: 0.35 | M11: 0.35
B12: 0.33263889 | C12: 0.33263889 | I12: 0.33263889 | L12: 0.33263889 | M12: 0.17291667
A15: 4 | B15: 0.079861111 | C15: 0.31805556 | D15: 0.11875 | F15: 0.21180556 | G15: 0.2375 | I15: 0.31736111 | L15: 0.31736111 | M15: 0.10347222
B16: 0.13125 | C16: 0.13125 | D16: 0.011111111 | F16: 0.049305556 | G16: 0.084027778 | I16: 0.13125 | L16: 0.13125 | M16: 0.08125
B17: 0.225 | C17: 0.14097222 | D17: 0.032638889 | I17: 0.34444444 | L17: 0.34444444 | M17: 0.34444444
C18: 0.084722222 | I18: 0.011111111 | L18: 0.011111111 | M18: 0.011111111
C19: 0.011111111 | I19: 0.032638889 | L19: 0.032638889 | M19: 0.032638889
A23: warmup | H23: quarter 1
A24: player | B24: total PL | C24: high PL | D24: tPL % | E24: hPL % | H24: player | I24: mins | J24: total PL | K24: high PL | L24: tPL % | M24: hPL %
A25: redacted 1 | B25: 171 | C25: 3 | D25: =B25/750 -> 0.228 | E25: =C25/200 -> 0.015 | H25: redacted 1 | I25: =SUM(B3:B6) -> 0.59375 | J25: 172 | K25: 58 | L25: =J25/750 -> 0.22933333 | M25: =K25/200 -> 0.29
A26: redacted 2 | B26: 163 | C26: 0 | D26: =B26/720 -> 0.22638889 | E26: =C26/65 -> 0 | H26: redacted 2 | I26: =SUM(C3:C6) -> 0.63888889 | J26: 141 | K26: 13 | L26: =J26/720 -> 0.19583333 | M26: =K26/65 -> 0.2
A27: redacted 3 | B27: 167 | C27: 1 | D27: =B27/750 -> 0.22266667 | E27: =C27/185 -> 0.0054054054 | H27: redacted 3 | I27: =SUM($D3:$D6) -> 0.19166667 | J27: 45 | K27: 6 | L27: =J27/750 -> 0.06 | M27: =K27/185 -> 0.032432432
A28: redacted 4 | B28: 153 | C28: 1 | D28: =B28/700 -> 0.21857143 | E28: =C28/220 -> 0.0045454545 | H28: redacted 4 | I28: =SUM(E3:E6) -> 0 | L28: =J28/700 -> 0 | M28: =K28/220 -> 0
A29: redacted 5 | B29: 170 | C29: 0 | D29: =B29/800 -> 0.2125 | E29: =C30/220 -> 0.022727273 | H29: redacted 5 | I29: =SUM(F3:F6) -> 0.29513889 | J29: 65 | K29: 11 | L29: =J29/800 -> 0.08125 | M29: =K29/220 -> 0.05
A30: redacted 6 | B30: 156 | C30: 5 | D30: =B30/820 -> 0.1902439 | E30: =C31/240 -> 0.020833333 | H30: redacted 6 | I30: =SUM(G3:G6) -> 0.48263889 | J30: 110 | K30: 16 | L30: =J30/820 -> 0.13414634 | M30: =K30/240 -> 0.066666667
A31: redacted 7 | B31: 180 | C31: 5 | D31: =B31/620 -> 0.29032258 | E31: =C32/90 -> 0.088888889 | H31: redacted 7 | I31: =SUM(H3:H6) -> 0 | L31: =J31/620 -> 0 | M31: =K31/90 -> 0
A32: redacted 8 | B32: 225 | C32: 8 | D32: =B32/820 -> 0.27439024 | E32: =C33/200 -> 0 | H32: redacted 8 | I32: =SUM(I3:I6) -> 0.35277778 | J32: 89 | K32: 17 | L32: =J32/820 -> 0.10853659 | M32: =K32/200 -> 0.085
A33: redacted 9 | B33: 123 | C33: 0 | D33: =B33/505 -> 0.24356436 | E33: =C34/42 -> 0.16666667 | H33: redacted 9 | I33: =SUM(J3:J6) -> 0 | L33: =J33/505 -> 0 | M33: =K33/42 -> 0
A34: redacted 10 | B34: 219 | C34: 7 | D34: =B34/740 -> 0.29594595 | E34: =C35/215 -> 0.013953488 | H34: redacted 10 | I34: =SUM(K3:K6) -> 0 | L34: =J34/740 -> 0 | M34: =K34/215 -> 0
A35: redacted 11 | B35: 189 | C35: 3 | D35: =B35/800 -> 0.23625 | E35: =C36/170 -> 0 | H35: redacted 11 | I35: =SUM(L3:L6) -> 0.4375 | J35: 123 | K35: 21 | L35: =J35/800 -> 0.15375 | M35: =K35/170 -> 0.12352941
A36: redacted 12 | B36: 134 | C36: 0 | D36: =B36/580 -> 0.23103448 | E36: =C37/75 -> 0.053333333 | H36: redacted 12 | I36: =SUM(M3:M6) -> 0.37916667 | J36: 92 | K36: 11 | L36: =J36/580 -> 0.15862069 | M36: =K36/75 -> 0.14666667
A37: redacted 13 | B37: 180 | C37: 4 | D37: =B37/720 -> 0.25 | E37: =C37/100 -> 0.04 | H37: redacted 13 | I37: =SUM(N3:N6) -> 0 | L37: =J37/720 -> 0 | M37: =K37/100 -> 0
A38: TOTALS | B38: =SUM(B25:B37) -> 2230 | C38: =SUM(C25:C37) -> 37 | D38: =SUM(D25:D37) -> 3.1198785 | E38: =SUM(E25:E37) -> 0.43135384 | H38: TOTALS | I38: =SUM(I25:I37)/5 -> 0.67430556 | J38: =SUM(J25:J37) -> 837 | K38: =SUM(K25:K37) -> 153 | L38: =SUM(L25:L37) -> 1.1214703 | M38: =SUM(M25:M37) -> 0.99429518
A40: quarter 2 | H40: quarter 3
A41: player | B41: mins | C41: total PL | D41: high PL | E41: tPL % | F41: hPL % | H41: player | I41: mins | J41: total PL | K41: high PL | L41: tPL % | M41: hPL %
A42: redacted 1 | B42: =SUM(B7:B10) -> 0.36041667 | C42: 103 | D42: 36 | E42: =C42/750 -> 0.13733333 | F42: =D42/200 -> 0.18 | H42: redacted 1 | I42: =SUM(B11:B14) -> 0.68263889 | J42: 151 | K42: 35 | L42: =J42/750 -> 0.20133333 | M42: =K42/200 -> 0.175
A43: redacted 2 | B43: =SUM(C7:C10) -> 0.57361111 | C43: 133 | D43: 11 | E43: =C43/720 -> 0.18472222 | F43: =D43/65 -> 0.16923077 | H43: redacted 2 | I43: =SUM(C11:C14) -> 0.68263889 | J43: 148 | K43: 8 | L43: =J43/720 -> 0.20555556 | M43: =K43/65 -> 0.12307692
A44: redacted 3 | B44: =SUM(D7:D10) -> 0.30625 | C44: 88 | D44: 15 | E44: =C44/750 -> 0.11733333 | F44: =D44/185 -> 0.081081081 | H44: redacted 3 | I44: =SUM(D11:D14) -> 0 | L44: =J44/750 -> 0 | M44: =K44/185 -> 0
A45: redacted 4 | B45: =SUM(E7:E10) -> 0 | E45: =C45/700 -> 0 | F45: =D45/220 -> 0 | H45: redacted 4 | I45: =SUM(E11:E14) -> 0 | L45: =J45/700 -> 0 | M45: =K45/220 -> 0
A46: redacted 5 | B46: =SUM(F7:F10) -> 0.28888889 | C46: 71 | D46: 11 | E46: =C46/800 -> 0.08875 | F46: =D46/220 -> 0.05 | H46: redacted 5 | I46: =SUM(F11:F14) -> 0.15902778 | J46: 36 | K46: 5 | L46: =J46/800 -> 0.045 | M46: =K46/220 -> 0.022727273
A47: redacted 6 | B47: =SUM(G7:G10) -> 0.097916667 | C47: 21 | D47: 5 | E47: =C47/820 -> 0.025609756 | F47: =D47/240 -> 0.020833333 | H47: redacted 6 | I47: =SUM(G11:G14) -> 0.31527778 | J47: 90 | K47: 15 | L47: =J47/820 -> 0.1097561 | M47: =K47/240 -> 0.0625
A48: redacted 7 | B48: =SUM(H7:H10) -> 0 | E48: =C48/620 -> 0 | F48: =D48/90 -> 0 | H48: redacted 7 | I48: =SUM(H11:H14) -> 0 | L48: =J48/620 -> 0 | M48: =K48/90 -> 0
A49: redacted 8 | B49: =SUM(I7:I10) -> 0.38263889 | C49: 98 | D49: 14 | E49: =C49/820 -> 0.1195122 | F49: =D49/200 -> 0.07 | H49: redacted 8 | I49: =SUM(I11:I14) -> 0.36666667 | J49: 89 | K49: 16 | L49: =J49/820 -> 0.10853659 | M49: =K49/200 -> 0.08
...

Sheet scrimmage and game numbers
A1: scrimmage and game data
B2: Tot PL | C2: PL Bands 3+ | D2: PL Per Minute | F2: Tot PL | G2: PL Bands 3+ | H2: PL Per Minute | J2: Tot PL | K2: PL Bands 3+ | L2: PL Per Minute | M2: high IMA
A3: Aliyahna Morris
A4: Scrimmage vs SCU | E4: Game vs Westmont | I4: Vanderbilt
A5: Warmup | B5: 142 | C5: 4 | D5: 4.28 | E5: Warmup | F5: 152 | G5: 3 | H5: 4.4 | I5: Warmup | J5: 128 | K5: 0 | L5: 5.36 | M5: 2
A6: Quarter 1 | B6: 202 | C6: 51 | D6: 11.54 | E6: Quarter 1 | F6: 165 | G6: 27 | H6: 13 | I6: Quarter 1 | J6: 145 | K6: 38 | L6: 11.65 | M6: 21
A7: Quarter 2 | B7: 90 | C7: 23 | D7: 14.96 | E7: Quarter 2 | F7: 109 | G7: 23 | H7: 11.28 | I7: Quarter 2 | J7: 152 | K7: 36 | L7: 11.21 | M7: 18
A8: Quarter 3 | B8: 107 | C8: 26 | D8: 9.43 | E8: Quarter 3 | F8: 86 | G8: 16 | H8: 10.75 | I8: Quarter 3 | J8: 134 | K8: 21 | L8: 10.12 | M8: 20
A9: Quarter 4 | B9: 95 | C9: 18 | D9: 9.56 | E9: Quarter 4 | F9: 54 | G9: 12 | H9: 9.34 | I9: Quarter 4 | J9: 134 | K9: 34 | L9: 10.11 | M9: 20
A10: Total | B10: 635 | C10: 122 | D10: 8.15 | E10: Total | F10: 567 | G10: 81 | H10: 8.01 | I10: Total | J10: 693 | K10: 129 | L10: 9.07 | M10: 81
A11: game total | B11: =B10-B5 -> 493 | C11: =C10-C5 -> 118 | D11: =AVERAGE(D6:D9) -> 11.3725 | E11: game total | F11: =F10-F5 -> 415 | G11: =G10-G5 -> 78 | H11: =AVERAGE(H6:H9) -> 11.0925 | I11: game total | J11: =J10-J5 -> 565 | K11: =K10-K5 -> 129 | L11: =AVERAGE(L6:L9) -> 10.7725 | M11: =M10-M5 -> 79
A12: Claudia Langarita
A13: Scrimmage vs SCU | E13: Game vs Westmont | I13: Vanderbilt
A14: Warmup | B14: 105 | C14: 4 | D14: 3.15 | E14: Warmup | F14: 154 | G14: 3 | H14: 4.47 | I14: Warmup | J14: 101 | K14: 1 | L14: 4.24 | M14: 0
A15: Quarter 1 | B15: 90 | C15: 19 | D15: 9.39 | E15: Quarter 1 | F15: 73 | G15: 8 | H15: 12.19 | I15: Quarter 1 | J15: 48 | K15: 3 | L15: 7.57 | M15: 6
A16: Quarter 2 | B16: 92 | C16: 14 | D16: 9.3 | E16: Quarter 3 | F16: 69 | G16: 4 | H16: 7.81 | I16: Quarter 2 | J16: 35 | K16: 2 | L16: 8.28 | M16: 8
E17: Quarter 4 | F17: 72 | G17: 4 | H17: 7.15 | I17: Quarter 3 | J17: 30 | K17: 5 | L17: 8.77 | M17: 3
A18: Total | B18: 287 | C18: 37 | D18: 5.44 | E18: Total | F18: 368 | G18: 19 | H18: 6.2 | I18: Total | J18: 214 | K18: 11 | L18: 5.66 | M18: 17
A19: game total | B19: =B18-B14 -> 182 | C19: =C18-C14 -> 33 | D19: =AVERAGE(D15:D16) -> 9.345 | E19: game total | F19: =F18-F14 -> 214 | G19: =G18-G14 -> 16 | H19: =AVERAGE(H15:H16) -> 10 | I19: game total | J19: =J18-J14 -> 113 | K19: =K18-K14 -> 10 | L19: =AVERAGE(L15:L16) -> 7.925 | M19: =M18-M14 -> 17
A20: Gisella Maul
A21: Scrimmage vs SCU | E21: Game vs Westmont | I21: Vanderbilt
A22: Warmup | B22: 168 | C22: 21 | D22: 5.04 | E22: Warmup | F22: 197 | G22: 12 | H22: 5.7 | I22: Warmup | J22: 144 | K22: 2 | L22: 6.04 | M22: 2
A23: Quarter 1 | B23: 133 | C23: 42 | D23: 12.44 | E23: Quarter 1 | F23: 103 | G23: 27 | H23: 14.02 | I23: Quarter 1 | J23: 31 | K23: 4 | L23: 11.58 | M23: 3
A24: Quarter 2 | B24: 76 | C24: 20 | D24: 12.35 | E24: Quarter 2 | F24: 75 | G24: 13 | H24: 12.74 | I24: Quarter 2 | J24: 64 | K24: 12 | L24: 11.03 | M24: 7
A25: Quarter 3 | B25: 135 | C25: 42 | D25: 9.1 | E25: Quarter 3 | F25: 48 | G25: 13 | H25: 11.22 | I25: Quarter 4 | J25: 42 | K25: 6 | L25: 10.81 | M25: 6
A26: Quarter 4 | B26: 166 | C26: 46 | D26: 9.88 | E26: Quarter 4 | F26: 54 | G26: 11 | H26: 10.4
A27: Total | B27: 677 | C27: 171 | D27: 8.29 | E27: Total | F27: 476 | G27: 76 | H27: 8.33 | I27: Total | J27: 282 | K27: 24 | L27: 7.77 | M27: 18
A28: game total | B28: =B27-B22 -> 509 | C28: =C27-C22 -> 150 | D28: =AVERAGE(D23:D26) -> 10.9425 | E28: game total | F28: =F27-F22 -> 279 | G28: =G27-G22 -> 64 | H28: =AVERAGE(H23:H26) -> 12.095 | I28: game total | J28: =J27-J22 -> 138 | K28: =K27-K22 -> 22 | L28: =AVERAGE(L23:L26) -> 11.14 | M28: =M27-M22 -> 16
A29: Lulu Laditan-Twidale
A30: Scrimmage vs SCU | E30: Game vs Westmont | I30: Vanderbilt
A31: Warmup | B31: 136 | C31: 6 | D31: 4.09 | E31: Warmup | F31: 165 | G31: 4 | H31: 4.78 | I31: Warmup | J31: 120 | K31: 4 | L31: 5.04 | M31: 1
A32: Quarter 1 | B32: 138 | C32: 44 | D32: 10.79 | E32: Quarter 1 | F32: 130 | G32: 19 | H32: 11.46 | I32: Quarter 1 | J32: 150 | K32: 27 | L32: 9.22 | M32: 11
A33: Quarter 2 | B33: 163 | C33: 47 | D33: 9.8 | E33: Quarter 2 | F33: 107 | G33: 15 | H33: 10.08 | I33: Quarter 2 | J33: 105 | K33: 19 | L33: 10.63 | M33: 8
A34: Quarter 3 | B34: 164 | C34: 44 | D34: 8.22 | E34: Quarter 3 | F34: 140 | G34: 20 | H34: 9.6 | I34: Quarter 3 | J34: 162 | K34: 28 | L34: 9.77 | M34: 19
A35: Quarter 4 | B35: 136 | C35: 40 | D35: 8.68 | I35: Quarter 4 | J35: 98 | K35: 10 | L35: 8.31 | M35: 5
A36: Total | B36: 738 | C36: 181 | D36: 7.5 | E36: Total | F36: 543 | G36: 58 | H36: 7.63 | I36: Total | J36: 635 | K36: 88 | L36: 8.11 | M36: 44
A37: game total | B37: =B36-B31 -> 602 | C37: =C36-C31 -> 175 | D37: =AVERAGE(D32:D35) -> 9.3725 | E37: game total | F37: =F36-F31 -> 378 | G37: =G36-G31 -> 54 | H37: =AVERAGE(H32:H35) -> 10.38 | I37: game total | J37: =J36-J31 -> 515 | K37: =K36-K31 -> 84 | L37: =AVERAGE(L32:L35) -> 9.4825 | M37: =M36-M31 -> 43
A38: Naya Ojukwu
A39: Scrimmage vs SCU | E39: Game vs Westmont | I39: missing
A40: Warmup | B40: 122 | C40: 1 | D40: 3.66 | E40: Warmup | F40: 174 | G40: 0 | H40: 5.03
...

Sheet warmup numbers
B1: Tot PL | C1: High IMA | D1: MII PL Interval 1 | E1: MII PL Interval 2 | F1: MII PL Interval 3
A2: Saint Mary's | I2: Average
A3: Anastasia Drosouni | B3: 197 | C3: 5 | D3: 15 | E3: 30 | F3: 49 | H3: st mary's | I3: {=_xludf.xlookup(I2,A:A,B:B)} -> #NAME?
A4: Gabrielle Abigor | B4: 193 | C4: 13 | D4: 14 | E4: 29 | F4: 45 | H4: idaho state | I4: {=_xludf.xlookup(I2,A15:A29,B15:B29)} -> #NAME?
A5: Kamryn Mafua | B5: 193 | C5: 7 | D5: 15 | E5: 29 | F5: 46 | H5: sjsu | I5: =B44 -> 204
A6: Kayla Williams | B6: 222 | C6: 4 | D6: 20 | E6: 39 | F6: 61 | H6: grambling | I6: =B59 -> 198
A7: Lola Donez | B7: 208 | C7: 10 | D7: 16 | E7: 31 | F7: 48 | H7: auburn | I7: =B73 -> 178
A8: Lulu Laditan-Twidale | B8: 187 | C8: 0 | D8: 14 | E8: 28 | F8: 46 | H8: michigan state | I8: 221
A9: Marta Suárez | B9: 179 | C9: 5 | D9: 15 | E9: 28 | F9: 46 | H9: arizona | I9: 175
A10: Michelle Onyiah | B10: 154 | C10: 11 | D10: 13 | E10: 22 | F10: 35 | H10: alabama | I10: 165
A11: Natalia Ackerman | B11: 150 | C11: 15 | D11: 14 | E11: 27 | F11: 42 | H11: pacific | I11: 164
A12: Sofia Bowes | B12: 206 | C12: 2 | D12: 16 | E12: 33 | F12: 53 | H12: stanford | I12: 194
A13: Zahra King | B13: 220 | C13: 7 | D13: 14 | E13: 31 | F13: 49 | H13: fordham | I13: 197
A14: Average | B14: 192 | C14: 7 | D14: 15 | E14: 30 | F14: 47 | H14: clemson | I14: 206
A15: Idaho State | H15: smu | I15: =AVERAGE(H1,I9:I14) -> 183.5
A16: Anastasia Drosouni | B16: 245 | C16: 5 | D16: 17 | E16: 36 | F16: 56 | H16: nc state | I16: 138
A17: Gabrielle Abigor | B17: 206 | C17: 26 | D17: 14 | E17: 31 | F17: 47 | H17: florida state | I17: 91
A18: Ioanna Krimili | B18: 187 | C18: 6 | D18: 16 | E18: 30 | F18: 46 | H18: duke | I18: 171
A19: Jayda Noble | B19: 169 | C19: 12 | D19: 11 | E19: 22 | F19: 37 | H19: wake forest | I19: 180
A20: Kamryn Mafua | B20: 191 | C20: 15 | D20: 13 | E20: 25 | F20: 39 | H20: unc | I20: 205
A21: Kayla Williams | B21: 229 | C21: 1 | D21: 20 | E21: 37 | F21: 57 | H21: louisville | I21: 201
A22: Lola Donez | B22: 206 | C22: 5 | D22: 16 | E22: 29 | F22: 43 | H22: notre dame | I22: 227
A23: Lulu Laditan-Twidale | B23: 192 | C23: 4 | D23: 13 | E23: 25 | F23: 41 | H23: boston college | I23: =AVERAGE(I9:I19,I22) -> 174.29167
A24: Marta Suárez | B24: 234 | C24: 9 | D24: 19 | E24: 37 | F24: 56 | H24: syracuse | I24: 214
A25: Michelle Onyiah | B25: 170 | C25: 9 | D25: 12 | E25: 22 | F25: 31 | H25: virginia | I25: 194
A26: Natalia Ackerman | B26: 172 | C26: 21 | D26: 13 | E26: 25 | F26: 38 | H26: virginia tech | I26: 185
A27: Sofia Bowes | B27: 212 | C27: 6 | D27: 16 | E27: 33 | F27: 50 | H27: georgia tech | I27: 173
A28: Zahra King | B28: 202 | C28: 7 | D28: 14 | E28: 29 | F28: 45 | H28: miami | I28: 189
A29: Average | B29: 201 | C29: 10 | D29: 15 | E29: 29 | F29: 45 | H29: virginia | I29: =AVERAGE(I17,I19,I20,I21,I22,I24:I28) -> 185.9
A30: SJSU | H30: notre dame | I30: 140
A31: Anastasia Drosouni | B31: 288 | C31: 4 | D31: 19 | E31: 31 | F31: 41
A32: Gabrielle Abigor | B32: 190 | C32: 19 | D32: 14 | E32: 25 | F32: 39 | H32: average warmup PL | I32: =AVERAGE(I3:I30) -> #NAME?
A33: Ioanna Krimili | B33: 174 | C33: 5 | D33: 17 | E33: 28 | F33: 36
A34: Jayda Noble | B34: 179 | C34: 13 | D34: 15 | E34: 26 | F34: 32
A35: Kamryn Mafua | B35: 205 | C35: 12 | D35: 13 | E35: 23 | F35: 35
A36: Kayla Williams | B36: 225 | C36: 2 | D36: 16 | E36: 31 | F36: 35
A37: Lola Donez | B37: 195 | C37: 6 | D37: 16 | E37: 27 | F37: 31
A38: Lulu Laditan-Twidale | B38: 185 | C38: 2 | D38: 15 | E38: 26 | F38: 30
A39: Marta Suárez | B39: 237 | C39: 12 | D39: 15 | E39: 26 | F39: 35
A40: Michelle Onyiah | B40: 174 | C40: 18 | D40: 14 | E40: 26 | F40: 30
...

Sheet games
B1: total PL | C1: ionna | D1: michelle | E1: marta | F1: kayla | G1: lulu | H1: starters % of total | I1: score | J1: score difference (+/-) | K1: win/loss
A2: Saint Mary's | B2: 2861 | C2: {=_xludf.xlookup(A2,ionna!A2:A31,ionna!B2:B31)} -> #NAME? | D2: 462 | E2: {=_xludf.xlookup(A2,marta!A2:A30,marta!B2:B30)} -> #NAME? | F2: {=_xludf.xlookup(A2,kayla!A2:A32,kayla!B2:B32)} -> #NAME? | G2: {=_xludf.xlookup(A2,lulu!A2:A32,lulu!B2:B32)} -> #NAME? | H2: =SUM(C2:G2)/B2 -> #NAME? | I2: 90-58 | J2: =90-58 -> 32 | K2: =IF(J2<0,0,1) -> 1
A3: Idaho State | B3: 3536 | C3: 449 | D3: 228 | E3: {=_xludf.xlookup(A3,marta!A3:A31,marta!B3:B31)} -> #NAME? | F3: {=_xludf.xlookup(A3,kayla!A3:A33,kayla!B3:B33)} -> #NAME? | G3: {=_xludf.xlookup(A3,lulu!A3:A33,lulu!B3:B33)} -> #NAME? | H3: =SUM(C3:G3)/B3 -> #NAME? | I3: 88-36 | J3: =88-36 -> 52 | K3: =IF(J3<0,0,1) -> 1
A4: SJSU | B4: 3314 | C4: 532 | D4: 289 | E4: {=_xludf.xlookup(A4,marta!A4:A32,marta!B4:B32)} -> #NAME? | F4: {=_xludf.xlookup(A4,kayla!A4:A34,kayla!B4:B34)} -> #NAME? | G4: {=_xludf.xlookup(A4,lulu!A4:A34,lulu!B4:B34)} -> #NAME? | H4: =SUM(C4:G4)/B4 -> #NAME? | I4: 82-53 | J4: =82-53 -> 29 | K4: =IF(J4<0,0,1) -> 1
A5: Gonzaga | B5: 5704 | C5: 857 | D5: 332 | E5: {=_xludf.xlookup(A5,marta!A5:A33,marta!B5:B33)} -> #NAME? | F5: {=_xludf.xlookup(A5,kayla!A5:A35,kayla!B5:B34)} -> #NAME? | G5: {=_xludf.xlookup(A5,lulu!A5:A35,lulu!B5:B34)} -> #NAME? | H5: =SUM(C5:G5)/B5 -> #NAME? | I5: 86-65 | J5: =86-65 -> 21 | K5: =IF(J5<0,0,1) -> 1
A6: Grambling | B6: 3680 | C6: 490 | D6: 338 | E6: {=_xludf.xlookup(A6,marta!A6:A34,marta!B6:B33)} -> #NAME? | F6: {=_xludf.xlookup(A6,kayla!A6:A36,kayla!B6:B36)} -> #NAME? | G6: {=_xludf.xlookup(A6,lulu!A6:A36,lulu!B6:B36)} -> #NAME? | H6: =SUM(C6:G6)/B6 -> #NAME? | I6: 86-63 | J6: =86-63 -> 23 | K6: =IF(J6<0,0,1) -> 1
A7: Auburn | B7: 3809 | C7: 730 | D7: 431 | E7: {=_xludf.xlookup(A7,marta!A7:A35,marta!B7:B35)} -> #NAME? | F7: {=_xludf.xlookup(A7,kayla!A7:A37,kayla!B7:B37)} -> #NAME? | G7: {=_xludf.xlookup(A7,lulu!A7:A37,lulu!B7:B37)} -> #NAME? | H7: =SUM(C7:G7)/B7 -> #NAME? | I7: 63-59 | J7: =62-59 -> 3 | K7: =IF(J7<0,0,1) -> 1
A8: Michigan State | B8: 2754 | C8: 475 | D8: 395 | E8: {=_xludf.xlookup(A8,marta!A8:A36,marta!B8:B36)} -> #NAME? | F8: {=_xludf.xlookup(A8,kayla!A8:A38,kayla!B8:B38)} -> #NAME? | G8: {=_xludf.xlookup(A8,lulu!A8:A38,lulu!B8:B38)} -> #NAME? | H8: =SUM(C8:G8)/B8 -> #NAME? | I8: 72-78 | J8: =72-78 -> -6 | K8: =IF(J8<0,0,1) -> 0
A9: Arizona | B9: 3378 | C9: 502 | D9: 493 | E9: {=_xludf.xlookup(A9,marta!A9:A37,marta!B9:B37)} -> #NAME? | F9: {=_xludf.xlookup(A9,kayla!A9:A39,kayla!B9:B39)} -> #NAME? | G9: {=_xludf.xlookup(A9,lulu!A9:A39,lulu!B9:B39)} -> #NAME? | H9: =SUM(C9:G9)/B9 -> #NAME? | I9: 74-62 | J9: =74-62 -> 12 | K9: =IF(J9<0,0,1) -> 1
A10: Alabama | B10: 3740 | C10: 735 | D10: 385 | E10: {=_xludf.xlookup(A10,marta!A10:A38,marta!B10:B38)} -> #NAME? | F10: {=_xludf.xlookup(A10,kayla!A10:A40,kayla!B10:B40)} -> #NAME? | G10: {=_xludf.xlookup(A10,lulu!A10:A40,lulu!B10:B40)} -> #NAME? | H10: =SUM(C10:G10)/B10 -> #NAME? | I10: 69-65 | J10: =69-65 -> 4 | K10: =IF(J10<0,0,1) -> 1
A11: Pacific | B11: 3710 | C11: 597 | D11: 366 | E11: {=_xludf.xlookup(A11,marta!A11:A39,marta!B11:B39)} -> #NAME? | F11: {=_xludf.xlookup(A11,kayla!A11:A41,kayla!B11:B41)} -> #NAME? | G11: {=_xludf.xlookup(A11,lulu!A11:A41,lulu!B11:B41)} -> #NAME? | H11: =SUM(C11:G11)/B11 -> #NAME? | I11: 74-66 | J11: =74-66 -> 8 | K11: =IF(J11<0,0,1) -> 1
A12: Stanford | B12: 3829 | C12: 630 | D12: 438 | E12: {=_xludf.xlookup(A12,marta!A12:A40,marta!B12:B40)} -> #NAME? | F12: {=_xludf.xlookup(A12,kayla!A12:A42,kayla!B12:B42)} -> #NAME? | G12: {=_xludf.xlookup(A12,lulu!A12:A42,lulu!B12:B42)} -> #NAME? | H12: =SUM(C12:G12)/B12 -> #NAME? | I12: 83-63 | J12: =83-63 -> 20 | K12: =IF(J12<0,0,1) -> 1
A13: Fordham | B13: 3427 | C13: 580 | D13: 363 | E13: {=_xludf.xlookup(A13,marta!A13:A41,marta!B13:B41)} -> #NAME? | F13: {=_xludf.xlookup(A13,kayla!A13:A43,kayla!B13:B43)} -> #NAME? | G13: {=_xludf.xlookup(A13,lulu!A13:A43,lulu!B13:B43)} -> #NAME? | H13: =SUM(C13:G13)/B13 -> #NAME? | I13: 69-53 | J13: =69-53 -> 16 | K13: =IF(J13<0,0,1) -> 1
A14: Temple | B14: 5886 | C14: 742 | D14: 464 | E14: {=_xludf.xlookup(A14,marta!A2:A30,marta!B2:B30)} -> #NAME? | F14: {=_xludf.xlookup(A14,kayla!A14:A44,kayla!B14:B44)} -> #NAME? | G14: {=_xludf.xlookup(A14,lulu!A14:A44,lulu!B14:B44)} -> #NAME? | H14: =SUM(C14:G14)/B14 -> #NAME? | I14: 89-63 | J14: =89-63 -> 26 | K14: =IF(J14<0,0,1) -> 1
A15: Clemson | B15: 3379 | C15: 643 | D15: 398 | E15: {=_xludf.xlookup(A15,marta!A3:A31,marta!B3:B31)} -> #NAME? | F15: {=_xludf.xlookup(A15,kayla!A15:A45,kayla!B15:B45)} -> #NAME? | G15: {=_xludf.xlookup(A15,lulu!A15:A45,lulu!B15:B45)} -> #NAME? | H15: =SUM(C15:G15)/B15 -> #NAME? | I15: 58-69 | J15: =58-69 -> -11 | K15: =IF(J15<0,0,1) -> 0
A16: SMU | B16: 3347 | C16: 629 | D16: 226 | E16: {=_xludf.xlookup(A16,marta!A4:A32,marta!B4:B32)} -> #NAME? | F16: {=_xludf.xlookup(A16,kayla!A16:A46,kayla!B16:B46)} -> #NAME? | G16: {=_xludf.xlookup(A16,lulu!A16:A46,lulu!B16:B46)} -> #NAME? | H16: =SUM(C16:G16)/B16 -> #NAME? | I16: 81-66 | J16: =81-66 -> 15 | K16: =IF(J16<0,0,1) -> 1
A17: NC State | B17: 3924 | C17: 690 | D17: 427 | E17: {=_xludf.xlookup(A17,marta!A5:A33,marta!B5:B33)} -> #NAME? | F17: {=_xludf.xlookup(A17,kayla!A17:A47,kayla!B17:B47)} -> #NAME? | G17: {=_xludf.xlookup(A17,lulu!A17:A47,lulu!B17:B47)} -> #NAME? | H17: =SUM(C17:G17)/B17 -> #NAME? | I17: 78-71 | J17: =78-71 -> 7 | K17: =IF(J17<0,0,1) -> 1
A18: Florida State | B18: 4648 | C18: 754 | D18: 370 | E18: {=_xludf.xlookup(A18,marta!A6:A34,marta!B6:B33)} -> #NAME? | F18: {=_xludf.xlookup(A18,kayla!A18:A48,kayla!B18:B48)} -> #NAME? | G18: {=_xludf.xlookup(A18,lulu!A18:A48,lulu!B18:B48)} -> #NAME? | H18: =SUM(C18:G18)/B18 -> #NAME? | I18: 82-70 | J18: =82-70 -> 12 | K18: =IF(J18<0,0,1) -> 1
A19: Duke | B19: 3530 | C19: 589 | D19: 288 | E19: {=_xludf.xlookup(A19,marta!A7:A35,marta!B7:B35)} -> #NAME? | F19: {=_xludf.xlookup(A19,kayla!A19:A49,kayla!B19:B49)} -> #NAME? | G19: {=_xludf.xlookup(A19,lulu!A19:A49,lulu!B19:B49)} -> #NAME? | H19: =SUM(C19:G19)/B19 -> #NAME? | I19: 38-72 | J19: =38-72 -> -34 | K19: =IF(J19<0,0,1) -> 0
A20: Wake Forest | B20: 3215 | C20: 789 | D20: 378 | E20: {=_xludf.xlookup(A20,marta!A8:A36,marta!B8:B36)} -> #NAME? | F20: {=_xludf.xlookup(A20,kayla!A20:A50,kayla!B20:B50)} -> #NAME? | G20: {=_xludf.xlookup(A20,lulu!A20:A50,lulu!B20:B50)} -> #NAME? | H20: =SUM(C20:G20)/B20 -> #NAME? | I20: 67-55 | J20: =67-55 -> 12 | K20: =IF(J20<0,0,1) -> 1
A21: Stanford | B21: 4242 | C21: 771 | D21: 396 | E21: {=_xludf.xlookup(A21,marta!A9:A37,marta!B9:B37)} -> #NAME? | F21: {=_xludf.xlookup(A21,kayla!A21:A51,kayla!B21:B51)} -> #NAME? | G21: {=_xludf.xlookup(A21,lulu!A21:A51,lulu!B21:B51)} -> #NAME? | H21: =SUM(C21:G21)/B21 -> #NAME? | I21: 75-72 | J21: =75-72 -> 3 | K21: =IF(J21<0,0,1) -> 1
A22: UNC | B22: 3283 | C22: 664 | D22: 313 | E22: {=_xludf.xlookup(A22,marta!A10:A38,marta!B10:B38)} -> #NAME? | F22: {=_xludf.xlookup(A22,kayla!A22:A52,kayla!B22:B52)} -> #NAME? | G22: {=_xludf.xlookup(A22,lulu!A22:A52,lulu!B22:B52)} -> #NAME? | H22: =SUM(C22:G22)/B22 -> #NAME? | I22: 52-65 | J22: =52-65 -> -13 | K22: =IF(J22<0,0,1) -> 0
A23: Louisville | B23: 3467 | C23: 729 | D23: 534 | E23: {=_xludf.xlookup(A23,marta!A11:A39,marta!B11:B39)} -> #NAME? | F23: {=_xludf.xlookup(A23,kayla!A23:A53,kayla!B23:B53)} -> #NAME? | G23: {=_xludf.xlookup(A23,lulu!A23:A53,lulu!B23:B53)} -> #NAME? | H23: =SUM(C23:G23)/B23 -> #NAME? | I23: 63-70 | J23: =63-70 -> -7 | K23: =IF(J23<0,0,1) -> 0
A24: Notre Dame | B24: 3685 | C24: 601 | D24: 404 | E24: {=_xludf.xlookup(A24,marta!A12:A40,marta!B12:B40)} -> #NAME? | F24: {=_xludf.xlookup(A24,kayla!A24:A54,kayla!B24:B54)} -> #NAME? | G24: {=_xludf.xlookup(A24,lulu!A24:A54,lulu!B24:B54)} -> #NAME? | H24: =SUM(C24:G24)/B24 -> #NAME? | I24: 52-91 | J24: =52-91 -> -39 | K24: =IF(J24<0,0,1) -> 0
A25: Boston College | B25: 4386 | C25: 579 | D25: 518 | E25: {=_xludf.xlookup(A25,marta!A13:A41,marta!B13:B41)} -> #NAME? | F25: {=_xludf.xlookup(A25,kayla!A25:A55,kayla!B25:B55)} -> #NAME? | G25: {=_xludf.xlookup(A25,lulu!A25:A55,lulu!B25:B55)} -> #NAME? | H25: =SUM(C25:G25)/B25 -> #NAME? | I25: 72-63 | J25: =72-63 -> 9 | K25: =IF(J25<0,0,1) -> 1
A26: Syracuse | B26: 4189 | C26: 942 | D26: 377 | E26: {=_xludf.xlookup(A26,marta!A14:A42,marta!B14:B42)} -> #NAME? | F26: {=_xludf.xlookup(A26,kayla!A26:A56,kayla!B26:B56)} -> #NAME? | G26: {=_xludf.xlookup(A26,lulu!A26:A56,lulu!B26:B56)} -> #NAME? | H26: =SUM(C26:G26)/B26 -> #NAME? | I26: 75-69 | J26: =75-69 -> 6 | K26: =IF(J26<0,0,1) -> 1
A27: Virginia | B27: 3013 | C27: 714 | D27: 382 | E27: {=_xludf.xlookup(A27,marta!A15:A43,marta!B15:B43)} -> #NAME? | F27: {=_xludf.xlookup(A27,kayla!A27:A57,kayla!B27:B57)} -> #NAME? | G27: {=_xludf.xlookup(A27,lulu!A27:A57,lulu!B27:B57)} -> #NAME? | H27: =SUM(C27:G27)/B27 -> #NAME? | I27: 76-70 | J27: =76-70 -> 6 | K27: =IF(J27<0,0,1) -> 1
A28: Virginia Tech | B28: 3582 | C28: 753 | D28: 228 | E28: {=_xludf.xlookup(A28,marta!A16:A44,marta!B16:B44)} -> #NAME? | F28: {=_xludf.xlookup(A28,kayla!A28:A58,kayla!B28:B58)} -> #NAME? | G28: {=_xludf.xlookup(A28,lulu!A28:A58,lulu!B28:B58)} -> #NAME? | H28: =SUM(C28:G28)/B28 -> #NAME? | I28: 84-87 | J28: =84-87 -> -3 | K28: =IF(J28<0,0,1) -> 0
A29: Georgia Tech | B29: 3139 | C29: 621 | D29: 484 | E29: {=_xludf.xlookup(A29,marta!A17:A45,marta!B17:B45)} -> #NAME? | F29: {=_xludf.xlookup(A29,kayla!A29:A59,kayla!B29:B59)} -> #NAME? | G29: {=_xludf.xlookup(A29,lulu!A29:A59,lulu!B29:B59)} -> #NAME? | H29: =SUM(C29:G29)/B29 -> #NAME? | I29: 79-65 | J29: =79-65 -> 14 | K29: =IF(J29<0,0,1) -> 1
A30: Miami | B30: 3244 | C30: 583 | D30: 425 | E30: {=_xludf.xlookup(A30,marta!A18:A46,marta!B18:B46)} -> #NAME? | F30: {=_xludf.xlookup(A30,kayla!A30:A60,kayla!B30:B60)} -> #NAME? | G30: {=_xludf.xlookup(A30,lulu!A30:A60,lulu!B30:B60)} -> #NAME? | H30: =SUM(C30:G30)/B30 -> #NAME? | I30: 82-63 | J30: =82-63 -> 19 | K30: =IF(J30<0,0,1) -> 1
A31: Virginia | B31: 3125 | C31: 657 | D31: 471 | E31: {=_xludf.xlookup(A31,marta!A19:A47,marta!B19:B47)} -> #NAME? | F31: {=_xludf.xlookup(A31,kayla!A31:A61,kayla!B31:B61)} -> #NAME? | G31: {=_xludf.xlookup(A31,lulu!A31:A61,lulu!B31:B61)} -> #NAME? | H31: =SUM(C31:G31)/B31 -> #NAME? | I31: 75-58 | J31: =75-58 -> 17 | K31: =IF(J31<0,0,1) -> 1
A32: Notre Dame | B32: 3460 | C32: 772 | D32: 468 | E32: {=_xludf.xlookup(A32,marta!A20:A48,marta!B20:B48)} -> #NAME? | F32: {=_xludf.xlookup(A32,kayla!A32:A62,kayla!B32:B62)} -> #NAME? | G32: {=_xludf.xlookup(A32,lulu!A32:A62,lulu!B32:B62)} -> #NAME? | H32: =SUM(C32:G32)/B32 -> #NAME? | I32: 64-73 | J32: =64-73 -> -9 | K32: =IF(J32<0,0,1) -> 0
A34: Average Game PL | B34: 3693

Sheet ionna
B1: Total PL | C1: High IMA | D1: MII 1 | E1: MII 2 | F1: MII 3 | G1: PL 3+ | J1: points | K1: minutes
A2: Idaho State | B2: 449 | C2: 41 | D2: 21 | E2: 43 | F2: 64 | G2: 92 | H2: 45603 | I2: Idaho St. | J2: 18 | K2: 23 | P2: 2 | Q2: 0 | R2: 0 | S2: 1 | T2: 1
A3: SJSU | B3: 532 | C3: 44 | D3: 18 | E3: 42 | F3: 58 | G3: 79 | H3: 45605 | I3: San Jose St. | J3: 18 | K3: 26 | P3: 4 | Q3: 0 | R3: 3 | S3: 0 | T3: 1
A4: Gonzaga | B4: 857 | C4: 46 | D4: 22 | E4: 48 | F4: 68 | G4: 127 | H4: 45610 | I4: Gonzaga | J4: 17 | K4: 36 | P4: 2 | Q4: 0 | R4: 2 | S4: 1 | T4: 0
A5: Grambling | B5: 490 | C5: 48 | D5: 21 | E5: 47 | F5: 67 | G5: 79 | H5: 45616 | I5: Grambling | J5: 15 | K5: 25 | P5: 1 | Q5: 0 | R5: 4 | S5: 0 | T5: 1
A6: Auburn | B6: 730 | C6: 74 | D6: 24 | E6: 44 | F6: 67 | G6: 122 | H6: 45618 | I6: Auburn | J6: 14 | K6: 37 | P6: 6 | Q6: 0 | R6: 1 | S6: 1 | T6: 1
A7: Michigan State | B7: 475 | C7: 48 | D7: 21 | E7: 45 | F7: 69 | G7: 85 | H7: 45622 | I7: Michigan St. | J7: 15 | K7: 33 | P7: 6 | Q7: 1 | R7: 2 | S7: 3 | T7: 1
A8: Arizona | B8: 502 | C8: 44 | D8: 19 | E8: 45 | F8: 58 | G8: 71 | H8: 45623 | I8: Arizona | J8: 7 | K8: 28 | P8: 5 | Q8: 0 | R8: 0 | S8: 3 | T8: 4
A9: Alabama | B9: 735 | C9: 68 | D9: 21 | E9: 47 | F9: 67 | G9: 116 | H9: 45631 | I9: Alabama | J9: 19 | K9: 37 | P9: 6 | Q9: 0 | R9: 0 | S9: 3 | T9: 3
A10: Pacific | B10: 597 | C10: 51 | D10: 21 | E10: 48 | F10: 71 | G10: 96 | H10: 45633 | I10: Pacific | J10: 22 | K10: 31 | P10: 3 | Q10: 0 | R10: 1 | S10: 3 | T10: 1
A11: Stanford | B11: 630 | C11: 56 | D11: 22 | E11: 47 | F11: 76 | G11: 122 | H11: 45639 | I11: Stanford | J11: 20 | K11: 33 | P11: 3 | Q11: 0 | R11: 2 | S11: 5 | T11: 3
A12: Fordham | B12: 580 | C12: 61 | D12: 23 | E12: 45 | F12: 68 | G12: 95 | H12: 45647 | I12: Fordham | J12: 19 | K12: 30 | P12: 2 | Q12: 0 | R12: 0 | S12: 1 | T12: 1
A13: Temple | B13: 742 | C13: 66 | D13: 19 | E13: 48 | F13: 71 | G13: 112 | H13: 45648 | I13: Temple | J13: 20 | K13: 29 | P13: 3 | Q13: 0 | R13: 1 | S13: 2 | T13: 1
... A23: Notre Dame | B23: 601 | C23: 57 | D23: 20 | E23: 46 | F23: 75 | G23: 109 | H23: 45697 | I23: Notre Dame | J23: 7 | K23: 35 | P23: 4 | Q23: 0 | R23: 1 | S23: 2 | T23: 2
A24: Boston College | B24: 579 | C24: =AVERAGE(C2:C23,C25:C31) -> 60.034483 | D24: 19 | E24: 43 | F24: 63 | G24: 54 | H24: 45701 | I24: Boston College | J24: 12 | K24: 29 | P24: 4 | Q24: 1 | R24: 1 | S24: 1 | T24: 2
A25: Syracuse | B25: 942 | C25: 98 | D25: 21 | E25: 47 | F25: 71 | G25: 162 | H25: 45704 | I25: Syracuse | J25: 6 | K25: 40 | P25: 3 | Q25: 0 | R25: 2 | S25: 6 | T25: 2
A26: Virginia | B26: 714 | C26: 61 | D26: 20 | E26: 44 | F26: 70 | G26: 108 | H26: 45708 | I26: Virginia | J26: 18 | K26: 40 | P26: 1 | Q26: 0 | R26: 4 | S26: 1 | T26: 2
A27: Virginia Tech | B27: 753 | C27: 77 | D27: 19 | E27: 43 | F27: 64 | G27: 115 | H27: 45711 | I27: Virginia Tech | J27: 19 | K27: 40 | P27: 2 | Q27: 0 | R27: 2 | S27: 5 | T27: 3
A28: Georgia Tech | B28: 621 | C28: 47 | D28: 20 | E28: 42 | F28: 65 | G28: 69 | H28: 45715 | I28: Georgia Tech | J28: 15 | K28: 38 | P28: 2 | Q28: 0 | R28: 2 | S28: 1 | T28: 3
A29: Miami | B29: 583 | C29: 44 | D29: 19 | E29: 44 | F29: 69 | G29: 90 | H29: 45718 | I29: Miami (FL) | J29: 10 | K29: 34 | P29: 4 | Q29: 0 | R29: 1 | S29: 1 | T29: 1
A30: Virginia | B30: 657 | C30: 43 | D30: 23 | E30: 53 | F30: 79 | G30: 96 | H30: 45722 | I30: Virginia | J30: 9 | K30: 36 | P30: 4 | Q30: 0 | R30: 0 | S30: 0 | T30: 1
A31: Notre Dame | B31: 772 | C31: 75 | D31: 21 | E31: 49 | F31: 78 | G31: 166 | H31: 45723 | I31: Notre Dame | J31: 7 | K31: 40 | P31: 3 | Q31: 0 | R31: 1 | S31: 1 | T31: 2
P32: 3 | Q32: 0 | R32: 0 | S32: 0 | T32: 2
A33: totals | B33: =SUM(B2:B31) -> 19799 | C33: =SUM(C2:C31) -> 1801.0345 | D33: =SUM(D2:D31) -> 617 | E33: =SUM(E2:E31) -> 1375 | F33: =SUM(F2:F31) -> 2053 | G33: =SUM(G2:G31) -> 3223 | I33: =COUNTA(I2:I31) -> 30 | K33: =SUM(K2:K31) -> 1028 | P33: 4 | Q33: 1 | R33: 0 | S33: 1 | T33: 1
P34: 4 | Q34: 0 | R34: 1 | S34: 4 | T34: 1
A35: average player load/game | B35: =B33/$I$33 -> 659.96667 | C35: =C33/$I$33 -> 60.034483 | D35: =D33/$I$33 -> 20.566667 | E35: =E33/$I$33 -> 45.833333 | F35: =F33/$I$33 -> 68.433333 | G35: =G33/$I$33 -> 107.43333 | I35: avg min/game | J35: =K33/I33 -> 34.266667 | P35: 0 | Q35: 0 | R35: 0 | S35: 2 | T35: 4
A36: average player load/min | B36: =B33/$K$33 -> 19.259728 | C36: =C33/$K$33 -> 1.7519791 | D36: =D33/$K$33 -> 0.60019455 | E36: =E33/$K$33 -> 1.3375486 | F36: =F33/$K$33 -> 1.9970817 | G36: =G33/$K$33 -> 3.135214
A37: max | B37: =MAX(B2:B31) -> 942 | C37: =MAX(C2:C31) -> 98 | D37: =MAX(D2:D31) -> 24 | E37: =MAX(E2:E31) -> 53 | F37: =MAX(F2:F31) -> 79 | G37: =MAX(G2:G31) -> 166
A38: std | B38: =STDEV(B2:B31) -> 115.55279 | C38: =STDEV(C2:C31) -> 16.67433 | D38: =STDEV(D2:D31) -> 1.4546793 | E38: =STDEV(E2:E31) -> 2.5741866 | F38: =STDEV(F2:F31) -> 5.0012642 | G38: =STDEV(G2:G31) -> 27.17083

Sheet michelle
B1: Total PL | C1: High IMA | D1: MII 1 | E1: MII 2 | F1: MII 3 | G1: PL 3+ | J1: points | K1: minutes
A2: Saint Mary's | B2: 462 | C2: 62 | D2: 17 | E2: 34 | F2: 53 | G2: 68 | H2: 45600 | I2: Saint Mary's (CA) | J2: 11 | K2: 29
A3: Idaho State | B3: 228 | C3: 30 | D3: 18 | E3: 40 | F3: 56 | G3: 45 | H3: 45603 | I3: Idaho St. | J3: 10 | K3: 15
A4: SJSU | B4: 289 | C4: 49 | D4: 18 | E4: 45 | F4: 60 | G4: 68 | H4: 45605 | I4: San Jose St. | J4: 8 | K4: 16
A5: Gonzaga | B5: 332 | C5: 31 | D5: 17 | E5: 36 | F5: 41 | G5: 33 | H5: 45610 | I5: Gonzaga | J5: 8 | K5: 11
A6: Grambling | B6: 338 | C6: 36 | D6: 18 | E6: 44 | F6: 50 | G6: 79 | H6: 45616 | I6: Grambling | J6: 4 | K6: 16
A7: Auburn | B7: 431 | C7: 55 | D7: 19 | E7: 37 | F7: 53 | G7: 79 | H7: 45618 | I7: Auburn | J7: 11 | K7: 24
A8: Michigan State | B8: 395 | C8: 52 | D8: 21 | E8: 41 | F8: 55 | G8: 73 | H8: 45622 | I8: Michigan St. | J8: 13 | K8: 22
A9: Arizona | B9: 493 | C9: 68 | D9: 18 | E9: 36 | F9: 51 | G9: 72 | H9: 45623 | I9: Arizona | J9: 25 | K9: 32
A10: Alabama | B10: 385 | C10: 47 | D10: 18 | E10: 45 | F10: 64 | G10: 62 | H10: 45631 | I10: Alabama | J10: 5 | K10: 22
A11: Pacific | B11: 366 | C11: 46 | D11: 20 | E11: 41 | F11: 54 | G11: 62 | H11: 45633 | I11: Pacific | J11: 15 | K11: 22
A12: Stanford | B12: 438 | C12: 53 | D12: 18 | E12: 40 | F12: 64 | G12: 88 | H12: 45639 | I12: Stanford | J12: 4 | K12: 26
A13: Fordham | B13: 363 | C13: 45 | D13: 17 | E13: 37 | F13: 55 | G13: 67 | H13: 45647 | I13: Fordham | J13: 15 | K13: 22
... A32: Notre Dame | B32: 468 | C32: 65 | D32: 19 | E32: 45 | F32: 70 | G32: 70 | H32: 45723 | I32: Notre Dame | J32: 13 | K32: 27
A34: totals | B34: =SUM(B3:B32) -> 11609 | C34: =SUM(C3:C32) -> 1466 | D34: =SUM(D3:D32) -> 557 | E34: =SUM(E3:E32) -> 1231 | F34: =SUM(F3:F32) -> 1723 | G34: =SUM(G3:G32) -> 1957 | I34: =COUNTA(I3:I32) -> 30 | K34: =SUM(K3:K32) -> 662
A36: average player load/game | B36: =B34/$I$34 -> 386.96667 | C36: =C34/$I$34 -> 48.866667 | D36: =D34/$I$34 -> 18.566667 | E36: =E34/$I$34 -> 41.033333 | F36: =F34/$I$34 -> 57.433333 | G36: =G34/$I$34 -> 65.233333 | I36: avg min/game | J36: =K34/I34 -> 22.066667
A37: average player load/minute | B37: =B34/$K$34 -> 17.536254 | C37: =C34/$K$34 -> 2.2145015 | D37: =D34/$K$34 -> 0.84138973 | E37: =E34/$K$34 -> 1.8595166 | F37: =F34/$K$34 -> 2.602719 | G37: =G34/$K$34 -> 2.9561934
A38: max | B38: =MAX(B2:B32) -> 534 | C38: =MAX(C2:C32) -> 74 | D38: =MAX(D2:D32) -> 22 | E38: =MAX(E2:E32) -> 49 | F38: =MAX(F2:F32) -> 70 | G38: =MAX(G2:G32) -> 95
A39: std | B39: =STDEV(B2:B32) -> 81.823256 | C39: =STDEV(C2:C32) -> 12.538457 | D39: =STDEV(D2:D32) -> 1.4345956 | E39: =STDEV(E2:E32) -> 4.0118105 | F39: =STDEV(F2:F32) -> 6.1492197 | G39: =STDEV(G2:G32) -> 16.302121

Sheet jayda
B1: Total PL | C1: High IMA | D1: MII 1 | E1: MII 2 | F1: MII 3 | G1: PL 3+ | J1: points | K1: minutes
A2: Idaho State | B2: 276 | C2: 32 | D2: 17 | E2: 40 | F2: 54 | G2: 41 | H2: 45603 | I2: Idaho St. | J2: 2 | K2: 13 | O2: 6 | S2: 0 | T2: 0
A3: SJSU | B3: 281 | C3: 41 | D3: 17 | E3: 35 | F3: 50 | G3: 32 | H3: 45605 | I3: San Jose St. | J3: 3 | K3: 15 | O3: 1 | S3: 0 | T3: 1
A4: Gonzaga | B4: 488 | C4: 63 | D4: 18 | E4: 44 | F4: 45 | G4: 56 | H4: 45610 | I4: Gonzaga | J4: 2 | K4: 20 | O4: 1 | S4: 1 | T4: 0
A5: Grambling | B5: 215 | C5: 37 | D5: 18 | E5: 36 | F5: 51 | G5: 51 | H5: 45616 | I5: Grambling | J5: 0 | K5: 13 | O5: 6 | S5: 0 | T5: 2
A6: Auburn | B6: 355 | C6: 62 | D6: 18 | E6: 42 | F6: 57 | G6: 93 | H6: 45618 | I6: Auburn | J6: 0 | K6: 15 | O6: 2 | S6: 3 | T6: 3
A7: Alabama | B7: 213 | C7: 37 | D7: 21 | E7: 39 | F7: 55 | G7: 50 | H7: 45631 | I7: Alabama | J7: 0 | K7: 9 | O7: 0 | S7: 2 | T7: 3
A8: Pacific | B8: 309 | C8: 35 | D8: 18 | E8: 45 | F8: 61 | G8: 62 | H8: 45633 | I8: Pacific | J8: 2 | K8: 16 | O8: 3 | S8: 0 | T8: 2
A9: Stanford | B9: 334 | C9: 31 | D9: 19 | E9: 40 | F9: 61 | G9: 57 | H9: 45639 | I9: Stanford | J9: 3 | K9: 18 | O9: 6 | S9: 0 | T9: 2
A10: Fordham | B10: 473 | C10: 66 | D10: 19 | E10: 38 | F10: 55 | G10: 69 | H10: 45647 | I10: Fordham | J10: 3 | K10: 28 | O10: 6 | S10: 0 | T10: 1
A11: Temple | B11: 534 | C11: 66 | D11: 19 | E11: 45 | F11: 64 | G11: 54 | H11: 45648 | I11: Temple | J11: 1 | K11: 23 | O11: 5 | S11: 1 | T11: 1
A12: Clemson | B12: 158 | C12: 18 | D12: 17 | E12: 35 | F12: n/a | G12: 35 | H12: 45659 | I12: Clemson | J12: 0 | K12: 9 | O12: 1 | S12: 4 | T12: 2
A13: SMU | B13: 398 | C13: 46 | D13: 18 | E13: 40 | F13: 55 | G13: 62 | H13: 45662 | I13: SMU | J13: 4 | K13: 24 | O13: 9 | S13: 1 | T13: 1
A14: NC State | B14: 428 | C14: 56 | D14: 19 | E14: 46 | F14: 59 | G14: 71 | H14: 45666 | I14: NC State | J14: 1 | K14: 23 | O14: 6 | S14: 1 | T14: 1
A15: Florida State | B15: 309 | C15: 30 | D15: 19 | E15: 42 | F15: 59 | G15: 42 | H15: 45669 | I15: Florida St. | J15: 0 | K15: 14 | O15: 3 | S15: 1 | T15: 1
A16: Duke | B16: 119 | C16: 15 | D16: 17 | E16: 35 | F16: 39 | G16: 19 | H16: 45673 | I16: Duke | J16: 0 | K16: 12 | O16: 1 | S16: 1 | T16: 2
A17: Wake Forest | B17: 212 | C17: 26 | D17: 19 | E17: 39 | F17: 61 | G17: 49 | H17: 45676 | I17: Wake Forest | J17: 0 | K17: 10 | O17: 2 | S17: 1 | T17: 1
A18: Game | B18: 354 | C18: 37 | D18: 17 | E18: 35 | F18: 48 | G18: 35 | H18: 45680 | I18: Stanford | J18: 1 | K18: 18 | O18: 5 | S18: 2 | T18: 1
A19: UNC | B19: 196 | C19: 32 | D19: 17 | E19: 38 | F19: 63 | G19: 30 | H19: 45687 | I19: North Carolina | J19: 2 | K19: 11 | O19: 2 | S19: 2 | T19: 2
A20: Louisville | B20: 285 | C20: 34 | D20: 21 | E20: 40 | F20: 65 | G20: 67 | H20: 45694 | I20: Louisville | J20: 0 | K20: 15 | O20: 2 | S20: 0 | T20: 4
A21: Notre Dame | B21: 292 | C21: 34 | D21: 22 | E21: 45 | F21: 72 | G21: 75 | H21: 45697 | I21: Notre Dame | J21: 3 | K21: 14 | O21: 3 | S21: 1 | T21: 4
A22: Boston College | B22: 311 | C22: 37 | D22: 17 | E22: 44 | F22: 25 | G22: 49 | H22: 45701 | I22: Boston College | J22: 6 | K22: 11 | O22: 3 | S22: 0 | T22: 0
A23: Syracuse | B23: 340 | C23: 34 | D23: 18 | E23: 39 | F23: 60 | G23: 74 | H23: 45704 | I23: Syracuse | J23: 4 | K23: 14 | O23: 1 | S23: 0 | T23: 0
A24: Virginia Tech | B24: 430 | C24: 46 | D24: 18 | E24: 41 | F24: 64 | G24: 63 | H24: 45711 | I24: Virginia Tech | J24: 5 | K24: 24 | O24: 1 | S24: 1 | T24: 0
... A27: Virginia | B27: 521 | C27: 61 | D27: 20 | E27: 43 | F27: 59 | G27: 129 | H27: 45722 | I27: Virginia | J27: 4 | K27: 27 | O27: 5 | S27: 0 | T27: 1
S28: 0 | T28: 1
A29: totals | B29: =SUM(B2:B27) -> 8454 | C29: =SUM(C2:C27) -> 1040 | D29: =SUM(D2:D27) -> 478 | E29: =SUM(E2:E27) -> 1048 | F29: =SUM(F2:F27) -> 1399 | G29: =SUM(G2:G27) -> 1469 | I29: =COUNTA(I2:I27) -> 26 | K29: =SUM(K2:K27) -> 432 | S29: 2 | T29: 1
A30: average PL/game | B30: =B29/$I$29 -> 325.15385 | C30: =C29/$I$29 -> 40 | D30: =D29/$I$29 -> 18.384615 | E30: =E29/$I$29 -> 40.307692 | F30: =F29/$I$29 -> 53.807692 | G30: =G29/$I$29 -> 56.5 | S30: 2 | T30: 2
A31: average PL/min | B31: =B29/$K$29 -> 19.569444 | C31: =C29/$K$29 -> 2.4074074 | D31: =D29/$K$29 -> 1.1064815 | E31: =E29/$K$29 -> 2.4259259 | F31: =F29/$K$29 -> 3.2384259 | G31: =G29/$K$29 -> 3.400463 | I31: avg min/game | J31: =K29/I29 -> 16.615385 | S31: 1 | T31: 3
A32: max | B32: =MAX(B2:B27) -> 534 | C32: =MAX(C2:C27) -> 66 | D32: =MAX(D2:D27) -> 22 | E32: =MAX(E2:E27) -> 46 | F32: =MAX(F2:F27) -> 72 | G32: =MAX(G2:G27) -> 129 | S32: 1 | T32: 3
A33: std | B33: =STDEV(B2:B27) -> 108.18528 | C33: =STDEV(C2:C27) -> 14.218298 | D33: =STDEV(D2:D27) -> 1.3878594 | E33: =STDEV(E2:E27) -> 3.3913918 | F33: =STDEV(F2:F27) -> 9.4889409 | G33: =STDEV(G2:G27) -> 22.045861

Sheet marta
B1: Total PL | C1: High IMA | D1: MII 1 | E1: MII 2 | F1: MII 3 | G1: PL 3+ | J1: points | K1: minutes
A2: Saint Mary's | B2: 397 | C2: 19 | D2: 16 | E2: 37 | F2: 58 | G2: 19 | H2: 45600 | I2: Saint Mary's (CA) | J2: 17 | K2: 26
A3: Idaho State | B3: 279 | C3: 18 | D3: 18 | E3: 37 | F3: 57 | G3: 30 | H3: 45603 | I3: Idaho St. | J3: 6 | K3: 18
A4: SJSU | B4: 265 | C4: 27 | D4: 18 | E4: 43 | F4: 57 | G4: 38 | H4: 45605 | I4: San Jose St. | J4: 10 | K4: 21
A5: Gonzaga | B5: 698 | C5: 56 | D5: 18 | E5: 42 | F5: 61 | G5: 55 | H5: 45610 | I5: Gonzaga | J5: 14 | K5: 35
A6: Grambling | B6: 359 | C6: 28 | D6: 21 | E6: 46 | F6: 62 | G6: 22 | H6: 45616 | I6: Grambling | J6: 16 | K6: 22
A7: Auburn | B7: 411 | C7: 42 | D7: 18 | E7: 41 | F7: 60 | G7: 34 | H7: 45618 | I7: Auburn | J7: 8 | K7: 25
A8: Michigan State | B8: 618 | C8: 45 | D8: 19 | E8: 42 | F8: 59 | G8: 74 | H8: 45622 | I8: Michigan St. | J8: 14 | K8: 38
A9: Arizona | B9: 258 | C9: 87 | D9: 14 | E9: 34 | F9: 51 | G9: 15 | H9: 45623 | I9: Arizona | J9: 4 | K9: 19
A10: Alabama | B10: 569 | C10: 51 | D10: 18 | E10: 44 | F10: 63 | G10: 37 | H10: 45631 | I10: Alabama | J10: 16 | K10: 32
A11: Pacific | B11: 502 | C11: 41 | D11: 17 | E11: 34 | F11: 49 | G11: 40 | H11: 45633 | I11: Pacific | J11: 21 | K11: 31
A12: Stanford | B12: 513 | C12: 49 | D12: 18 | E12: 41 | F12: 65 | G12: 46 | H12: 45639 | I12: Stanford | J12: 21 | K12: 31
A13: Temple | B13: 62 | C13: 0 | D13: 4 | E13: 9 | F13: 11 | G13: 1 | H13: 45659 | I13: Clemson | J13: 12 | K13: 35
... A30: Notre Dame | B30: 220 | C30: 23 | D30: 19 | E30: 48 | F30: 77 | G30: 38 | H30: 45723 | I30: Notre Dame | J30: 14 | K30: 32
A33: total | B33: =SUM(B3:B31) -> 13135 | C33: =SUM(C3:C31) -> 1286 | D33: =SUM(D3:D31) -> 497 | E33: =SUM(E3:E31) -> 1141 | F33: =SUM(F3:F31) -> 1670 | G33: =SUM(G3:G31) -> 1345 | I33: =COUNTA(I2:I30) -> 29 | K33: =SUM(K2:K30) -> 862
A34: average PL/game | B34: =B33/$I$33 -> 452.93103 | C34: =C33/$I$33 -> 44.344828 | D34: =D33/$I$33 -> 17.137931 | E34: =E33/$I$33 -> 39.344828 | F34: =F33/$I$33 -> 57.586207 | G34: =G33/$I$33 -> 46.37931
A35: average PL/min | B35: =B33/$K$33 -> 15.237819 | C35: =C33/$K$33 -> 1.4918794 | D35: =D33/$K$33 -> 0.57656613 | E35: =E33/$K$33 -> 1.3236659 | F35: =F33/$K$33 -> 1.937355 | G35: =G33/$K$33 -> 1.5603248 | H35: avg min/game | I35: =K33/I33 -> 29.724138
A36: max | B36: =MAX(B2:B30) -> 698 | C36: =MAX(C2:C30) -> 87 | D36: =MAX(D2:D30) -> 21 | E36: =MAX(E2:E30) -> 48 | F36: =MAX(F2:F30) -> 77 | G36: =MAX(G2:G30) -> 84
A37: std | B37: =STDEV(B2:B30) -> 146.18907 | C37: =STDEV(C2:C30) -> 16.621844 | D37: =STDEV(D2:D30) -> 2.9411301 | E37: =STDEV(E2:E30) -> 6.9354874 | F37: =STDEV(F2:F30) -> 10.808453 | G37: =STDEV(G2:G30) -> 19.823296

Sheet kayla
B1: Total PL | C1: High IMA | D1: MII 1 | E1: MII 2 | F1: MII 3 | G1: PL 3+
A2: Saint Mary's | B2: 563 | C2: 98 | D2: 24 | E2: 49 | F2: 75 | G2: 170 | H2: 45600 | I2: Saint Mary's (CA) | J2: 9 | K2: 25
A3: Idaho State | B3: 480 | C3: 46 | D3: 21 | E3: 43 | F3: 68 | G3: 114 | H3: 45603 | I3: Idaho St. | J3: 11 | K3: 25
A4: SJSU | B4: 492 | C4: 62 | D4: 19 | E4: 42 | F4: 61 | G4: 120 | H4: 45605 | I4: San Jose St. | J4: 16 | K4: 26
A5: Gonzaga | B5: 878 | C5: 59 | D5: 21 | E5: 49 | F5: 71 | G5: 209 | H5: 45610 | I5: Gonzaga | J5: 25 | K5: 35
A6: Grambling | B6: 518 | C6: 66 | D6: 22 | E6: 47 | F6: 70 | G6: 169 | H6: 45616 | I6: Grambling | J6: 8 | K6: 23
A7: Auburn | B7: 734 | C7: 74 | D7: 25 | E7: 48 | F7: 68 | G7: 214 | H7: 45618 | I7: Auburn | J7: 7 | K7: 33
A8: Michigan State | B8: 182 | C8: 16 | D8: 20 | E8: 43 | F8: 69 | G8: 74 | H8: 45622 | I8: Michigan St. | J8: 3 | K8: 25
A9: Arizona | B9: 624 | C9: 80 | D9: 21 | E9: 48 | F9: 71 | G9: 190 | H9: 45623 | I9: Arizona | J9: 7 | K9: 31
A10: Alabama | B10: 755 | C10: 79 | D10: 23 | E10: 55 | F10: 76 | G10: 238 | H10: 45631 | I10: Alabama | J10: 21 | K10: 36
A11: Pacific | B11: 759 | C11: 94 | D11: 21 | E11: 43 | F11: 63 | G11: 224 | H11: 45633 | I11: Pacific | J11: 5 | K11: 35
A12: Stanford | B12: 671 | C12: 71 | D12: 22 | E12: 47 | F12: 72 | G12: 198 | H12: 45639 | I12: Stanford | J12: 13 | K12: 34
A13: Fordham | B13: 596 | C13: 89 | D13: 18 | E13: 42 | F13: 70 | G13: 154 | H13: 45647 | I13: Fordham | J13: 8 | K13: 33
... A32: Notre Dame | B32: 757 | C32: 63 | D32: 22 | E32: 51 | F32: 80 | G32: 227 | H32: 45723 | I32: Notre Dame | J32: 14 | K32: 37
A34: total | B34: =SUM(B2:B32) -> 19206 | C34: =SUM(C2:C32) -> 2245 | D34: =SUM(D2:D32) -> 665 | E34: =SUM(E2:E32) -> 1473 | F34: =SUM(F2:F32) -> 2209 | G34: =SUM(G2:G32) -> 5386 | I34: =COUNTA(I2:I32) -> 31 | K34: =SUM(K2:K32) -> 981
A35: average PL/game | B35: =B34/$I$34 -> 619.54839 | C35: =C34/$I$34 -> 72.419355 | D35: =D34/$I$34 -> 21.451613 | E35: =E34/$I$34 -> 47.516129 | F35: =F34/$I$34 -> 71.258065 | G35: =G34/$I$34 -> 173.74194
A36: average PL/min | B36: =B34/$K$34 -> 19.577982 | C36: =C34/$K$34 -> 2.2884811 | D36: =D34/$K$34 -> 0.67787971 | E36: =E34/$K$34 -> 1.5015291 | F36: =F34/$K$34 -> 2.2517839 | G36: =G34/$K$34 -> 5.490316 | H36: avg min/game | I36: =K34/I34 -> 31.645161
A37: max | B37: =MAX(B2:B32) -> 878 | C37: =MAX(C2:C32) -> 107 | D37: =MAX(D2:D32) -> 25 | E37: =MAX(E2:E32) -> 55 | F37: =MAX(F2:F32) -> 86 | G37: =MAX(G2:G32) -> 242
A38: std | B38: =STDEV(B2:B32) -> 157.03351 | C38: =STDEV(C2:C32) -> 20.774623 | D38: =STDEV(D2:D32) -> 1.6296975 | E38: =STDEV(E2:E32) -> 3.6043582 | F38: =STDEV(F2:F32) -> 5.7327582 | G38: =STDEV(G2:G32) -> 45.977507

Sheet gabi
B1: Total PL | C1: High IMA | D1: MII 1 | E1: MII 2 | F1: MII 3 | G1: PL 3+ | J1: points | K1: minutes
A2: Saint Mary's | B2: 72 | C2: 7 | D2: 16 | E2: 35 | F2: 51 | G2: 11 | H2: 45600 | I2: Saint Mary's (CA) | J2: 0 | K2: 3 | T2: 0
A3: Idaho State | B3: 219 | C3: 45 | D3: 17 | E3: 33 | F3: 53 | G3: 29 | H3: 45603 | I3: Idaho St. | J3: 8 | K3: 10 | T3: 0
A4: SJSU | B4: 141 | C4: 19 | D4: 15 | E4: 33 | F4: 51 | G4: 25 | H4: 45605 | I4: San Jose St. | J4: 2 | K4: 11 | T4: 3
A5: Gonzaga | B5: 184 | C5: 13 | D5: 17 | E5: 27 | F5: 43 | G5: 5 | H5: 45610 | I5: Gonzaga | J5: 0 | K5: 1 | T5: 0
A6: Grambling | B6: 197 | C6: 44 | D6: 16 | E6: 34 | F6: 48 | G6: 36 | H6: 45616 | I6: Grambling | J6: 11 | K6: 11 | T6: 4
A7: Auburn | B7: 154 | C7: 20 | D7: 16 | E7: 40 | F7: 58 | G7: 36 | H7: 45618 | I7: Auburn | J7: 0 | K7: 8 | T7: 2
A8: Michigan State | B8: 271 | C8: 32 | D8: 23 | E8: 31 | F8: 49 | G8: 58 | H8: 45622 | I8: Michigan St. | J8: 4 | K8: 15 | T8: 3
A9: Arizona | B9: 142 | C9: 23 | D9: 20 | E9: 44 | F9: 57 | G9: 29 | H9: 45623 | I9: Arizona | J9: 0 | K9: 8 | T9: 0
A10: Alabama | B10: 185 | C10: 24 | D10: 18 | E10: 39 | F10: 58 | G10: 33 | H10: 45631 | I10: Alabama | J10: 2 | K10: 11 | T10: 2
A11: Pacific | B11: 244 | C11: 38 | D11: 17 | E11: 38 | F11: 48 | G11: 39 | H11: 45633 | I11: Pacific | J11: 0 | K11: 13 | T11: 1
A12: Stanford | B12: 42 | C12: 8 | D12: 19 | E12: 5 | F12: 6 | G12: 10 | H12: 45639 | I12: Stanford | J12: 0 | K12: 2 | T12: 0
A13: Fordham | B13: 245 | C13: 47 | D13: 16 | E13: 37 | F13: 56 | G13: 41 | H13: 45647 | I13: Fordham | J13: 6 | K13: 15 | T13: 2
A14: Temple | B14: 407 | C14: 61 | D14: 19 | E14: 40 | F14: 61 | G14: 36 | H14: 45648 | I14: Temple | J14: 6 | K14: 13 | T14: 2
A15: Clemson | B15: 47 | C15: 3 | D15: 18 | E15: 44 | F15: n/a | G15: 10 | H15: 45659 | I15: Clemson | J15: 0 | K15: 3 | T15: 0
A16: SMU | B16: 150 | C16: 25 | D16: 18 | E16: 34 | F16: n/a | G16: 29 | H16: 45662 | I16: SMU | J16: 2 | K16: 9 | T16: 2
A17: NC State | B17: 326 | C17: 39 | D17: 18 | E17: 45 | F17: 63 | G17: 52 | H17: 45666 | I17: NC State | J17: 4 | K17: 16 | T17: 2
A18: Florida State | B18: 305 | C18: 36 | D18: 19 | E18: 46 | F18: 64 | G18: 46 | H18: 45669 | I18: Florida St. | J18: 4 | K18: 15 | T18: 2
A19: Duke | B19: 204 | C19: 38 | D19: 20 | E19: 41 | F19: 36 | G19: 40 | H19: 45673 | I19: Duke | J19: 4 | K19: 11 | T19: 2
A20: Wake Forest | B20: 133 | C20: 21 | D20: 18 | E20: 41 | F20: 47 | G20: 30 | H20: 45676 | I20: Wake Forest | J20: 2 | K20: 7 | T20: 2
A21: Game | B21: 86 | C21: 19 | D21: 13 | E21: 22 | F21: 27 | G21: 8 | H21: 45680 | I21: Stanford | J21: 2 | K21: 2 | T21: 1
A22: UNC | B22: 221 | C22: 30 | D22: 19 | E22: 38 | F22: 64 | G22: 44 | H22: 45687 | I22: North Carolina | J22: 0 | K22: 15 | T22: 0
A23: Louisville | B23: 40 | C23: 6 | D23: 19 | E23: 39 | F23: n/a | G23: 6 | H23: 45694 | I23: Louisville | J23: 0 | K23: 3 | T23: 1
A24: Notre Dame | B24: 65 | C24: 8 | D24: 22 | E24: n/a | F24: n/a | G24: 21 | H24: 45697 | I24: Notre Dame | J24: 0 | K24: 3 | T24: 2
A25: Boston College | B25: 117 | C25: 7 | D25: 18 | E25: 21 | F25: 28 | G25: 6 | H25: 45701 | I25: Boston College | J25: 0 | K25: 3 | T25: 0
A26: Syracuse | B26: 193 | C26: 27 | D26: 17 | E26: 39 | F26: 52 | G26: 46 | H26: 45704 | I26: Syracuse | J26: 3 | K26: 10 | T26: 1
A27: Virginia | B27: 76 | C27: 14 | D27: 16 | E27: 37 | F27: 61 | G27: 7 | H27: 45708 | I27: Virginia | J27: 2 | K27: 5 | T27: 0
A28: Virginia Tech | B28: 76 | C28: 8 | D28: 16 | E28: 32 | F28: n/a | G28: 6 | H28: 45711 | I28: Virginia Tech | J28: 2 | K28: 5 | T28: 4
A29: Georgia Tech | B29: 96 | C29: 15 | D29: 20 | E29: 41 | F29: n/a | G29: 17 | H29: 45715 | I29: Georgia Tech | J29: 3 | K29: 6 | T29: 0
A30: Miami | B30: 79 | C30: 9 | D30: 18 | E30: 39 | F30: 25 | G30: 16 | H30: 45718 | I30: Miami (FL) | J30: 0 | K30: 4 | T30: 0
A31: Virginia | B31: 134 | C31: 20 | D31: 18 | E31: 33 | F31: 43 | G31: 16 | H31: 45722 | I31: Virginia | J31: 2 | K31: 6 | T31: 1
A32: Notre Dame | B32: 183 | C32: 34 | D32: 18 | E32: 37 | F32: 53 | G32: 33 | H32: 45723 | I32: Notre Dame | J32: 0 | K32: 8 | T32: 1
T33: 0
A34: total | B34: =SUM(B2:B32) -> 5034 | C34: =SUM(C2:C32) -> 740 | D34: =SUM(D2:D32) -> 554 | E34: =SUM(E2:E32) -> 1065 | F34: =SUM(F2:F32) -> 1202 | G34: =SUM(G2:G32) -> 821 | I34: =COUNTA(I2:I32) -> 31 | K34: =SUM(K2:K32) -> 252 | T34: 2
A36: avg PL/game | B36: =B34/$I$34 -> 162.3871 | C36: =C34/$I$34 -> 23.870968 | D36: =D34/$I$34 -> 17.870968 | E36: =E34/$I$34 -> 34.354839 | F36: =F34/$I$34 -> 38.774194 | G36: =G34/$I$34 -> 26.483871 | J36: avg mins/game | K36: =K34/I34 -> 8.1290323
A37: avg PL/minute | B37: =B34/$K$34 -> 19.97619 | C37: =C34/$K$34 -> 2.9365079 | D37: =D34/$K$34 -> 2.1984127 | E37: =E34/$K$34 -> 4.2261905 | F37: =F34/$K$34 -> 4.7698413 | G37: =G34/$K$34 -> 3.2579365
A38: max | B38: =MAX(B2:B32) -> 407 | C38: =MAX(C2:C32) -> 61 | D38: =MAX(D2:D32) -> 23 | E38: =MAX(E2:E32) -> 46 | F38: =MAX(F2:F32) -> 64 | G38: =MAX(G2:G32) -> 58
A39: std | B39: =STDEV(B2:B32) -> 89.726131 | C39: =STDEV(C2:C32) -> 14.65092 | D39: =STDEV(D2:D32) -> 1.9956943 | E39: =STDEV(E2:E32) -> 8.2952001 | F39: =STDEV(F2:F32) -> 14.191899 | G39: =STDEV(G2:G32) -> 15.511009

Sheet lulu
B1: Total PL | C1: High IMA | D1: MII 1 | E1: MII 2 | F1: MII 3 | G1: PL 3+ | J1: points | K1: minutes
A2: Saint Mary's | B2: 504 | C2: 33 | D2: 16 | E2: 37 | F2: 56 | G2: 72 | H2: 45600 | I2: Saint Mary's (CA) | J2: 24 | K2: 28
A3: Idaho State | B3: 389 | C3: 28 | D3: 16 | E3: 39 | F3: 54 | G3: 43 | H3: 45603 | I3: Idaho St. | J3: 13 | K3: 24
A4: SJSU | B4: 381 | C4: 23 | D4: 16 | E4: 36 | F4: 49 | G4: 50 | H4: 45605 | I4: San Jose St. | J4: 14 | K4: 24
A5: Gonzaga | B5: 678 | C5: 36 | D5: 17 | E5: 42 | F5: 57 | G5: 92 | H5: 45610 | I5: Gonzaga | J5: 18 | K5: 31
A6: Grambling | B6: 409 | C6: 37 | D6: 15 | E6: 37 | F6: 53 | G6: 59 | H6: 45616 | I6: Grambling | J6: 19 | K6: 24
A7: Auburn | B7: 649 | C7: 57 | D7: 18 | E7: 38 | F7: 58 | G7: 114 | H7: 45618 | I7: Auburn | J7: 22 | K7: 38
A8: Michigan State | B8: 242 | C8: 18 | D8: 18 | E8: 34 | F8: 52 | G8: 36 | H8: 45622 | I8: Michigan St. | J8: 20 | K8: 37
A9: Arizona | B9: 435 | C9: 45 | D9: 15 | E9: 32 | F9: 50 | G9: 59 | H9: 45623 | I9: Arizona | J9: 18 | K9: 29
A10: Alabama | B10: 615 | C10: 43 | D10: 18 | E10: 44 | F10: 61 | G10: 83 | H10: 45631 | I10: Alabama | J10: 4 | K10: 36
A11: Pacific | B11: 507 | C11: 35 | D11: 17 | E11: 44 | F11: 59 | G11: 59 | H11: 45633 | I11: Pacific | J11: 9 | K11: 30
A12: Stanford | B12: 575 | C12: 49 | D12: 20 | E12: 41 | F12: 65 | G12: 92 | H12: 45639 | I12: Stanford | J12: 20 | K12: 33
A13: Fordham | B13: 524 | C13: 45 | D13: 15 | E13: 35 | F13: 56 | G13: 57 | H13: 45647 | I13: Fordham | J13: 10 | K13: 33
... A32: Notre Dame | B32: 610 | C32: 52 | D32: 18 | E32: 44 | F32: 69 | G32: 136 | H32: 45723 | I32: Notre Dame | J32: 16 | K32: 35
A34: total | B34: =SUM(B4:B32) -> 15313 | C34: =SUM(C4:C32) -> 1140 | D34: =SUM(D4:D32) -> 521 | E34: =SUM(E4:E32) -> 1156 | F34: =SUM(F4:F32) -> 1702 | G34: =SUM(G4:G32) -> 2477 | I34: =COUNTA(I4:I32) -> 29 | K34: =SUM(K4:K32) -> 922
A35: average PL/game | B35: =B34/$I$34 -> 528.03448 | C35: =C34/$I$34 -> 39.310345 | D35: =D34/$I$34 -> 17.965517 | E35: =E34/$I$34 -> 39.862069 | F35: =F34/$I$34 -> 58.689655 | G35: =G34/$I$34 -> 85.413793
A36: average PL/min | B36: =B34/$K$34 -> 16.60846 | C36: =C34/$K$34 -> 1.2364425 | D36: =D34/$K$34 -> 0.56507592 | E36: =E34/$K$34 -> 1.2537961 | F36: =F34/$K$34 -> 1.845987 | G36: =G34/$K$34 -> 2.686551 | I36: avg mins/game | J36: =K34/I34 -> 31.793103
A37: max | B37: =MAX(B2:B32) -> 726 | C37: =MAX(C2:C32) -> 61 | D37: =MAX(D2:D32) -> 22 | E37: =MAX(E2:E32) -> 52 | F37: =MAX(F2:F32) -> 74 | G37: =MAX(G2:G32) -> 209
A38: std | B38: =STDEV(B2:B32) -> 122.54025 | C38: =STDEV(C2:C32) -> 10.639448 | D38: =STDEV(D2:D32) -> 1.8636304 | E38: =STDEV(E2:E32) -> 4.1147519 | F38: =STDEV(F2:F32) -> 5.2841821 | G38: =STDEV(G2:G32) -> 35.200073

Sheet lola
B1: Total PL | C1: High IMA | D1: MII 1 | E1: MII 2 | F1: MII 3 | G1: PL 3+ | J1: points | K1: minutes
A2: Saint Mary's | B2: 317 | C2: 20 | D2: 17 | E2: 36 | F2: 49 | G2: 35 | H2: 45600 | I2: Saint Mary's (CA) | J2: 1 | K2: 17
A3: Idaho State | B3: 370 | C3: 23 | D3: 16 | E3: 35 | F3: 52 | G3: 43 | H3: 45603 | I3: Idaho St. | J3: 0 | K3: 23
A4: SJSU | B4: 353 | C4: 30 | D4: 16 | E4: 33 | F4: 50 | G4: 53 | H4: 45605 | I4: San Jose St. | J4: 0 | K4: 19
A5: Gonzaga | B5: 407 | C5: 22 | D5: 19 | E5: 34 | F5: 41 | G5: 35 | H5: 45610 | I5: Gonzaga | J5: 0 | K5: 13
A6: Grambling | B6: 232 | C6: 23 | D6: 16 | E6: 36 | F6: 46 | G6: 29 | H6: 45616 | I6: Grambling | J6: 3 | K6: 11
A7: Auburn | B7: 238 | C7: 20 | D7: 19 | E7: 36 | F7: 50 | G7: 48 | H7: 45618 | I7: Auburn | J7: 1 | K7: 14
A8: Michigan State | B8: 391 | C8: 31 | D8: 18 | E8: 39 | F8: 57 | G8: 54 | H8: 45622 | I8: Michigan St. | J8: 2 | K8: 23
A9: Arizona | B9: 466 | C9: 30 | D9: 18 | E9: 40 | F9: 55 | G9: 62 | H9: 45623 | I9: Arizona | J9: 1 | K9: 28
A10: Alabama | B10: 128 | C10: 10 | D10: 18 | E10: 38 | F10: 55 | G10: 20 | H10: 45631 | I10: Alabama | J10: 0 | K10: 8
A11: Pacific | B11: 192 | C11: 11 | D11: 18 | E11: 42 | F11: 63 | G11: 30 | H11: 45633 | I11: Pacific | J11: 0 | K11: 10
A12: Stanford | B12: 189 | C12: 16 | D12: 20 | E12: 35 | F12: 57 | G12: 28 | H12: 45639 | I12: Stanford | J12: 0 | K12: 9
A13: Wake Forest | B13: 4 | C13: 0 | D13: n/a | E13: n/a | F13: n/a | G13: 0 | H13: 45676 | I13: Wake Forest | J13: 0 | K13: 2
A14: Game | B14: 274 | C14: 15 | D14: 17 | E14: 38 | F14: 49 | G14: 37 | H14: 45680 | I14: Stanford | J14: 2 | K14: 12
A15: UNC | B15: 211 | C15: 14 | D15: 15 | E15: 33 | F15: 49 | G15: 31 | H15: 45687 | I15: North Carolina | J15: 3 | K15: 14
A16: Louisville | B16: 98 | C16: 6 | D16: 17 | E16: 37 | F16: n/a | G16: 18 | H16: 45694 | I16: Louisville | J16: 0 | K16: 6
A17: Notre Dame | B17: 127 | C17: 11 | D17: 16 | E17: 37 | F17: 54 | G17: 17 | H17: 45697 | I17: Notre Dame | J17: 0 | K17: 8
A18: Boston College | B18: 214 | C18: 13 | D18: 15 | E18: 38 | F18: 59 | G18: 17 | H18: 45701 | I18: Boston College | J18: 0 | K18: 10
A19: Virginia | B19: 93 | C19: 7 | D19: 17 | E19: 33 | F19: 32 | G19: 12 | H19: 45708 | I19: Virginia | J19: 0 | K19: 6
A20: Virginia Tech | B20: 66 | C20: 2 | D20: 17 | E20: 36 | F20: 55 | G20: 6 | H20: 45711 | I20: Virginia Tech | J20: 0 | K20: 4
A21: Georgia Tech | B21: 59 | C21: 3 | D21: 14 | E21: n/a | F21: n/a | G21: 7 | H21: 45715 | I21: Georgia Tech | J21: 0 | K21: 4
A22: Miami | B22: 106 | C22: 6 | D22: 17 | E22: 37 | F22: 52 | G22: 16 | H22: 45718 | I22: Miami (FL) | J22: 0 | K22: 6
A23: Virginia | B23: 24 | C23: 0 | D23: 11 | E23: 23 | F23: n/a | G23: 2 | H23: 45722 | I23: Virginia | J23: 0 | K23: 1
A24: Notre Dame | B24: 40 | C24: 2 | D24: 16 | E24: 31 | F24: n/a | G24: 7 | H24: 45723 | I24: Notre Dame | J24: 0 | K24: 2
A26: total | B26: =SUM(B2:B24) -> 4599 | C26: =SUM(C2:C24) -> 315 | D26: =SUM(D2:D24) -> 367 | E26: =SUM(E2:E24) -> 747 | F26: =SUM(F2:F24) -> 925 | G26: =SUM(G2:G24) -> 607 | I26: =COUNTA(I2:I24) -> 23 | K26: =SUM(K2:K24) -> 250
A28: avg PL/game | B28: =B26/$I$26 -> 199.95652 | C28: =C26/$I$26 -> 13.695652 | D28: =D26/$I$26 -> 15.956522 | E28: =E26/$I$26 -> 32.478261 | F28: =F26/$I$26 -> 40.217391 | G28: =G26/$I$26 -> 26.391304 | I28: avg min/game | J28: =K26/I26 -> 10.869565
A29: avg PL/min | B29: =B26/$K$26 -> 18.396 | C29: =C26/$K$26 -> 1.26 | D29: =D26/$K$26 -> 1.468 | E29: =E26/$K$26 -> 2.988 | F29: =F26/$K$26 -> 3.7 | G29: =G26/$K$26 -> 2.428
A30: max | B30: =MAX(B2:B24) -> 466 | C30: =MAX(C2:C24) -> 31 | D30: =MAX(D2:D24) -> 20 | E30: =MAX(E2:E24) -> 42 | F30: =MAX(F2:F24) -> 63 | G30: =MAX(G2:G24) -> 62
A31: std | B31: =STDEV(B2:B24) -> 134.5972 | C31: =STDEV(C2:C24) -> 9.8046129 | D31: =STDEV(D2:D24) -> 1.9120262 | E31: =STDEV(E2:E24) -> 3.8674466 | F31: =STDEV(F2:F24) -> 7.0137587 | G31: =STDEV(G2:G24) -> 17.642251

Sheet dros
